Workbook
Name _Toc59337654_3: #REF!
Name _Toc59337654_3: #REF!
Name _Toc59337654_3: #REF!
Name _Toc59337654_3: #REF!
Name _Toc59337654_3: #REF!
Name _Toc59337654_3: #REF!
Name _Toc59337655_3: #REF!
Name _Toc59337655_3: #REF!
Name _Toc59337655_3: #REF!
Name _Toc59337655_3: #REF!
Name _Toc59337655_3: #REF!
Name _Toc59337655_3: #REF!
Name _Toc59337688_42: #REF!
Name _Toc59337688_42: #REF!
Name _Toc59337688_42: #REF!
Name _Toc59337688_42: #REF!
Name _Toc59337694_46: [2]Дефекты!#REF!
Name _Toc59337694_46: [2]Дефекты!#REF!
Name _Toc59337694_46: [2]Дефекты!#REF!
Name _Toc59337694_46: [2]Дефекты!#REF!
Name _Toc59337694_46: [2]Дефекты!#REF!
Name _Toc59337694_46: [2]Дефекты!#REF!
Name _Toc59337694_47: #REF!
Name _Toc59337694_47: #REF!
Name _Toc59337694_47: #REF!
Name _Toc59337694_47: #REF!
Name _Toc59337694_47: #REF!
Name _Toc59337694_47: #REF!
Name _Toc59337695_48: #REF!
Name _Toc59337695_48: #REF!
Name _Toc59337695_48: #REF!
Name _Toc59337695_48: #REF!
Name _Toc59337695_48: #REF!
Name _Toc59337695_48: #REF!
Name _Toc59337701_35: #REF!
Name _Toc59337701_35: #REF!
Name _Toc59337701_35: #REF!
Name _Toc59337701_35: #REF!
Name _Toc59337701_35: #REF!
Name _Toc59337701_35: #REF!
Name _Toc59337704_38: #REF!
Name _Toc59337704_38: #REF!
Name _Toc59337704_38: #REF!
Name _Toc59337704_38: #REF!
Name _Toc59337705_39: #REF!
Name _Toc59337705_39: #REF!
Name _Toc59337705_39: #REF!
Name _Toc59337705_39: #REF!
Name Database: #REF!
Name Database: #REF!
Name Database: #REF!
Name Database: #REF!
Name Database: #REF!
Name Database: #REF!
Name Excel_BuiltIn_Database: #REF!
Name Excel_BuiltIn_Database: #REF!
Name Excel_BuiltIn_Database: #REF!
Name Excel_BuiltIn_Database: #REF!
Name Excel_BuiltIn_Database: #REF!
Name Excel_BuiltIn_Database: #REF!

Sheet Ввод данных
A1: Наименование объекта | B1: Водовод высокого давления «Т. вр. (скв. 194) – скв.194»
A2: Инвентарный номер объекта | B2: 124000045136
A3: Диаметр, толщина стенки, мм | B3: 89х8,0
A4: Длина, м | B4: 20
A5: Тип изоляции | B5: Лента ПВХ
B6: ПК00+00 – ПК00+20
A8: Ответственный исполнитель | B8: Н. А. Тажитдинов
A10: Исполнитель | B10: А. Р. Салимов
A11: уд. | B11: уд. № 0069-0963 до 30.04.2028
C26: 8

Sheet 1 шаблон
A2: № | B2: Пикет | C2: Ду, мм | D2: Sном,
D3: мм | G3: из отчета (приложение 12) вставляем только эти строки, они автоматически перенесутся на лист толщинометрия
A4: 1 | B4: 2 | C4: 3 | D4: 4
A5: Секция 30 | B5: 00+20 | C5: 65 | D5: 16 | G5: выполнять начинаем с прил 13 (твердометрия), т.к. данные по стали переносятся в прил 12 и от этого зависит отбраковочная толщина
A6: ЗМС
A53: Секция 10 | B53: 00+10 | C53: 89 | D53: 8
A54: Шурф № 1
A56: Секция 20 | B56: 00+20 | C56: 89 | D56: 8
A57: труба

Sheet 2 Приложение 13
A1: Для ОК, ЗКЛ, ЗДШ | K1: Выбираем марку стали (если в разных элементах она разная учитываем это). В зависимости от стали, выбираем граничные значения твердости в ячейке т.1, растягиваем на поле нужного размера. Далее копируем только ЗНАЧЕНИЯ на след. Вкладку | O1: Сталь 20
A2: № секции | B2: наим секции | C2: Пикет | D2: Диаметр, мм | E2: Марка стали | F2: Результаты измерений: НВ | O2: 137 | P2: 153
D3: мм | E3: стали | F3: т.1 | G3: т.2 | H3: т.3 | I3: т.4
A4: 1 | B4: 1 | C4: 2 | D4: 3 | E4: 4 | F4: 5 | G4: 6 | H4: 7 | I4: 8 | O4: Сталь 10
A5: ='1 шаблон'!A5 -> Секция 30 | B5: ='1 шаблон'!A6 -> ЗМС | C5: ='1 шаблон'!B5 -> 00+20 | D5: ='1 шаблон'!C5 -> 65 | E5: =O1 -> Сталь 20 | F5: =IF($E5=$O$1,RANDBETWEEN($O$2,$P$2),IF($E5=$O$4,RANDBETWEEN($O$5,$P$5),IF($E5=$O$7,RANDBETWEEN($O$8,$P$8),IF($E5=$O$10,RANDBETWEEN($O$11,$P$11),IF($E5=$O$13,RANDBETWEEN($O$14,$P$14),IF($E5=$O$16,RANDBETWEEN($O$17,$P$17),IF($E5=$O$19,RANDBETWEEN($O$20,$P$20),IF($E5=$O$22,RANDBETWEEN($O$23,$P$23),IF($E5=$O$25,RANDBETWEEN($O$26,$P$26),IF($E5=$O$28,RANDBETWEEN($O$29,$P$29),"0")))))))))) -> 141 | G5: =IF($E5=$O$1,RANDBETWEEN($O$2,$P$2),IF($E5=$O$4,RANDBETWEEN($O$5,$P$5),IF($E5=$O$7,RANDBETWEEN($O$8,$P$8),IF($E5=$O$10,RANDBETWEEN($O$11,$P$11),IF($E5=$O$13,RANDBETWEEN($O$14,$P$14),IF($E5=$O$16,RANDBETWEEN($O$17,$P$17),IF($E5=$O$19,RANDBETWEEN($O$20,$P$20),IF($E5=$O$22,RANDBETWEEN($O$23,$P$23),IF($E5=$O$25,RANDBETWEEN($O$26,$P$26),IF($E5=$O$28,RANDBETWEEN($O$29,$P$29),"0")))))))))) -> 149 | H5: =IF($E5=$O$1,RANDBETWEEN($O$2,$P$2),IF($E5=$O$4,RANDBETWEEN($O$5,$P$5),IF($E5=$O$7,RANDBETWEEN($O$8,$P$8),IF($E5=$O$10,RANDBETWEEN($O$11,$P$11),IF($E5=$O$13,RANDBETWEEN($O$14,$P$14),IF($E5=$O$16,RANDBETWEEN($O$17,$P$17),IF($E5=$O$19,RANDBETWEEN($O$20,$P$20),IF($E5=$O$22,RANDBETWEEN($O$23,$P$23),IF($E5=$O$25,RANDBETWEEN($O$26,$P$26),IF($E5=$O$28,RANDBETWEEN($O$29,$P$29),"0")))))))))) -> 149 | I5: =IF($E5=$O$1,RANDBETWEEN($O$2,$P$2),IF($E5=$O$4,RANDBETWEEN($O$5,$P$5),IF($E5=$O$7,RANDBETWEEN($O$8,$P$8),IF($E5=$O$10,RANDBETWEEN($O$11,$P$11),IF($E5=$O$13,RANDBETWEEN($O$14,$P$14),IF($E5=$O$16,RANDBETWEEN($O$17,$P$17),IF($E5=$O$19,RANDBETWEEN($O$20,$P$20),IF($E5=$O$22,RANDBETWEEN($O$23,$P$23),IF($E5=$O$25,RANDBETWEEN($O$26,$P$26),IF($E5=$O$28,RANDBETWEEN($O$29,$P$29),"0")))))))))) -> 151 | O5: 125 | P5: 143
A6: ='1 шаблон'!A7 -> 0 | B6: ='1 шаблон'!A8 -> 0 | C6: ='1 шаблон'!B7 -> 0 | D6: ='1 шаблон'!C7 -> 0 | E6: =O1 -> Сталь 20 | F6: =IF($E6=$O$1,RANDBETWEEN($O$2,$P$2),IF($E6=$O$4,RANDBETWEEN($O$5,$P$5),IF($E6=$O$7,RANDBETWEEN($O$8,$P$8),IF($E6=$O$10,RANDBETWEEN($O$11,$P$11),IF($E6=$O$13,RANDBETWEEN($O$14,$P$14),IF($E6=$O$16,RANDBETWEEN($O$17,$P$17),IF($E6=$O$19,RANDBETWEEN($O$20,$P$20),IF($E6=$O$22,RANDBETWEEN($O$23,$P$23),IF($E6=$O$25,RANDBETWEEN($O$26,$P$26),IF($E6=$O$28,RANDBETWEEN($O$29,$P$29),"0")))))))))) -> 153 | G6: =IF($E6=$O$1,RANDBETWEEN($O$2,$P$2),IF($E6=$O$4,RANDBETWEEN($O$5,$P$5),IF($E6=$O$7,RANDBETWEEN($O$8,$P$8),IF($E6=$O$10,RANDBETWEEN($O$11,$P$11),IF($E6=$O$13,RANDBETWEEN($O$14,$P$14),IF($E6=$O$16,RANDBETWEEN($O$17,$P$17),IF($E6=$O$19,RANDBETWEEN($O$20,$P$20),IF($E6=$O$22,RANDBETWEEN($O$23,$P$23),IF($E6=$O$25,RANDBETWEEN($O$26,$P$26),IF($E6=$O$28,RANDBETWEEN($O$29,$P$29),"0")))))))))) -> 147 | H6: =IF($E6=$O$1,RANDBETWEEN($O$2,$P$2),IF($E6=$O$4,RANDBETWEEN($O$5,$P$5),IF($E6=$O$7,RANDBETWEEN($O$8,$P$8),IF($E6=$O$10,RANDBETWEEN($O$11,$P$11),IF($E6=$O$13,RANDBETWEEN($O$14,$P$14),IF($E6=$O$16,RANDBETWEEN($O$17,$P$17),IF($E6=$O$19,RANDBETWEEN($O$20,$P$20),IF($E6=$O$22,RANDBETWEEN($O$23,$P$23),IF($E6=$O$25,RANDBETWEEN($O$26,$P$26),IF($E6=$O$28,RANDBETWEEN($O$29,$P$29),"0")))))))))) -> 145 | I6: =IF($E6=$O$1,RANDBETWEEN($O$2,$P$2),IF($E6=$O$4,RANDBETWEEN($O$5,$P$5),IF($E6=$O$7,RANDBETWEEN($O$8,$P$8),IF($E6=$O$10,RANDBETWEEN($O$11,$P$11),IF($E6=$O$13,RANDBETWEEN($O$14,$P$14),IF($E6=$O$16,RANDBETWEEN($O$17,$P$17),IF($E6=$O$19,RANDBETWEEN($O$20,$P$20),IF($E6=$O$22,RANDBETWEEN($O$23,$P$23),IF($E6=$O$25,RANDBETWEEN($O$26,$P$26),IF($E6=$O$28,RANDBETWEEN($O$29,$P$29),"0")))))))))) -> 146
A7: ='1 шаблон'!A9 -> 0 | B7: ='1 шаблон'!A10 -> 0 | C7: ='1 шаблон'!B9 -> 0 | D7: ='1 шаблон'!C9 -> 0 | E7: =O13 -> Сталь 20Л | O7: Сталь 25Л
A8: ='1 шаблон'!A11 -> 0 | B8: ='1 шаблон'!A12 -> 0 | C8: ='1 шаблон'!B11 -> 0 | D8: ='1 шаблон'!C11 -> 0 | E8: =O13 -> Сталь 20Л | O8: 121 | P8: 151
A9: ='1 шаблон'!A13 -> 0 | B9: ='1 шаблон'!A14 -> 0 | C9: ='1 шаблон'!B13 -> 0 | D9: ='1 шаблон'!C13 -> 0 | E9: =O13 -> Сталь 20Л
A10: ='1 шаблон'!A15 -> 0 | B10: ='1 шаблон'!A16 -> 0 | C10: ='1 шаблон'!B15 -> 0 | D10: ='1 шаблон'!C15 -> 0 | E10: =O1 -> Сталь 20 | O10: Сталь 20Л | Q10: (если Д<100)
A11: ='1 шаблон'!A17 -> 0 | B11: ='1 шаблон'!A18 -> 0 | C11: ='1 шаблон'!B17 -> 0 | D11: ='1 шаблон'!C17 -> 0 | E11: =O1 -> Сталь 20 | O11: 116 | P11: 144
A12: ='1 шаблон'!A19 -> 0 | B12: ='1 шаблон'!A20 -> 0 | C12: ='1 шаблон'!B19 -> 0 | D12: ='1 шаблон'!C19 -> 0 | E12: =O1 -> Сталь 20
A13: ='1 шаблон'!A21 -> 0 | B13: ='1 шаблон'!A22 -> 0 | C13: ='1 шаблон'!B21 -> 0 | D13: ='1 шаблон'!C21 -> 0 | E13: =O1 -> Сталь 20 | O13: Сталь 20Л | Q13: (если Д>100)
A14: ='1 шаблон'!A23 -> 0 | B14: ='1 шаблон'!A24 -> 0 | C14: ='1 шаблон'!B23 -> 0 | D14: ='1 шаблон'!C23 -> 0 | E14: =O1 -> Сталь 20 | O14: 111 | P14: 156
A15: ='1 шаблон'!A25 -> 0 | B15: ='1 шаблон'!A26 -> 0 | C15: ='1 шаблон'!B25 -> 0 | D15: ='1 шаблон'!C25 -> 0 | E15: =O1 -> Сталь 20
A16: ='1 шаблон'!A27 -> 0 | B16: ='1 шаблон'!A28 -> 0 | C16: ='1 шаблон'!B27 -> 0 | D16: ='1 шаблон'!C27 -> 0 | E16: =O1 -> Сталь 20 | O16: Сталь 3сп
A17: ='1 шаблон'!A29 -> 0 | B17: ='1 шаблон'!A30 -> 0 | C17: ='1 шаблон'!B29 -> 0 | D17: ='1 шаблон'!C29 -> 0 | E17: =O13 -> Сталь 20Л | O17: 111 | P17: 156
A18: ='1 шаблон'!A31 -> 0 | B18: ='1 шаблон'!A32 -> 0 | C18: ='1 шаблон'!B31 -> 0 | D18: ='1 шаблон'!C31 -> 0 | E18: =O13 -> Сталь 20Л
A19: ='1 шаблон'!A33 -> 0 | B19: ='1 шаблон'!A34 -> 0 | C19: ='1 шаблон'!B33 -> 0 | D19: ='1 шаблон'!C33 -> 0 | E19: =O13 -> Сталь 20Л | O19: Сталь 09Г2С
A20: ='1 шаблон'!A35 -> 0 | B20: ='1 шаблон'!A36 -> 0 | C20: ='1 шаблон'!B35 -> 0 | D20: ='1 шаблон'!C35 -> 0 | E20: =O13 -> Сталь 20Л | O20: 135 | P20: 152
A21: ='1 шаблон'!A37 -> 0 | B21: ='1 шаблон'!A38 -> 0 | C21: ='1 шаблон'!B37 -> 0 | D21: ='1 шаблон'!C37 -> 0 | E21: =O13 -> Сталь 20Л
A22: ='1 шаблон'!A39 -> 0 | B22: ='1 шаблон'!A40 -> 0 | C22: ='1 шаблон'!B39 -> 0 | D22: ='1 шаблон'!C39 -> 0 | E22: =$O$1 -> Сталь 20 | O22: Сталь 15
A23: ='1 шаблон'!A41 -> 0 | B23: ='1 шаблон'!A42 -> 0 | C23: ='1 шаблон'!B41 -> 0 | D23: ='1 шаблон'!C41 -> 0 | E23: =$O$1 -> Сталь 20 | O23: 137 | P23: 148
A24: ='1 шаблон'!A43 -> 0 | B24: ='1 шаблон'!A44 -> 0 | C24: ='1 шаблон'!B43 -> 0 | D24: ='1 шаблон'!C43 -> 0 | E24: =$O$1 -> Сталь 20
A25: ='1 шаблон'!A45 -> 0 | B25: ='1 шаблон'!A46 -> 0 | C25: ='1 шаблон'!B45 -> 0 | D25: ='1 шаблон'!C45 -> 0 | E25: =$O$1 -> Сталь 20 | O25: Сталь 25
O26: 162 | P26: 170
O28: Сталь 30ХМ
O29: 200 | P29: 250
A30: Трубопровод
A31: № секции | B31: Наим. секции | C31: Пикет | D31: Диаметр, мм | E31: Марка стали | F31: Результаты измерений: НВ
D32: мм | E32: стали | F32: т.1 | G32: т.2 | H32: т.3 | I32: т.4 | J32: т.5 | K32: т.6
A33: 1 | B33: 1 | C33: 2 | D33: 3 | E33: 4 | F33: 5 | G33: 6 | H33: 7 | I33: 8 | J33: 9 | K33: 10
A34: ='1 шаблон'!A53 -> Секция 10 | B34: ='1 шаблон'!A54 -> Шурф № 1 | C34: ='1 шаблон'!B53 -> 00+10 | D34: ='1 шаблон'!C53 -> 89 | E34: =$O$1 -> Сталь 20 | F34: =IF($E34=$O$1,RANDBETWEEN($O$2,$P$2),IF($E34=$O$4,RANDBETWEEN($O$5,$P$5),IF($E34=$O$7,RANDBETWEEN($O$8,$P$8),IF($E34=$O$10,RANDBETWEEN($O$11,$P$11),IF($E34=$O$13,RANDBETWEEN($O$14,$P$14),IF($E34=$O$16,RANDBETWEEN($O$17,$P$17),IF($E34=$O$19,RANDBETWEEN($O$20,$P$20),IF($E34=$O$22,RANDBETWEEN($O$23,$P$23),IF($E34=$O$25,RANDBETWEEN($O$26,$P$26),IF($E34=$O$28,RANDBETWEEN($O$29,$P$29),"0")))))))))) -> 139 | G34: =IF($E34=$O$1,RANDBETWEEN($O$2,$P$2),IF($E34=$O$4,RANDBETWEEN($O$5,$P$5),IF($E34=$O$7,RANDBETWEEN($O$8,$P$8),IF($E34=$O$10,RANDBETWEEN($O$11,$P$11),IF($E34=$O$13,RANDBETWEEN($O$14,$P$14),IF($E34=$O$16,RANDBETWEEN($O$17,$P$17),IF($E34=$O$19,RANDBETWEEN($O$20,$P$20),IF($E34=$O$22,RANDBETWEEN($O$23,$P$23),IF($E34=$O$25,RANDBETWEEN($O$26,$P$26),IF($E34=$O$28,RANDBETWEEN($O$29,$P$29),"0")))))))))) -> 151 | H34: =IF($E34=$O$1,RANDBETWEEN($O$2,$P$2),IF($E34=$O$4,RANDBETWEEN($O$5,$P$5),IF($E34=$O$7,RANDBETWEEN($O$8,$P$8),IF($E34=$O$10,RANDBETWEEN($O$11,$P$11),IF($E34=$O$13,RANDBETWEEN($O$14,$P$14),IF($E34=$O$16,RANDBETWEEN($O$17,$P$17),IF($E34=$O$19,RANDBETWEEN($O$20,$P$20),IF($E34=$O$22,RANDBETWEEN($O$23,$P$23),IF($E34=$O$25,RANDBETWEEN($O$26,$P$26),IF($E34=$O$28,RANDBETWEEN($O$29,$P$29),"0")))))))))) -> 152 | I34: =IF($E34=$O$1,RANDBETWEEN($O$2,$P$2),IF($E34=$O$4,RANDBETWEEN($O$5,$P$5),IF($E34=$O$7,RANDBETWEEN($O$8,$P$8),IF($E34=$O$10,RANDBETWEEN($O$11,$P$11),IF($E34=$O$13,RANDBETWEEN($O$14,$P$14),IF($E34=$O$16,RANDBETWEEN($O$17,$P$17),IF($E34=$O$19,RANDBETWEEN($O$20,$P$20),IF($E34=$O$22,RANDBETWEEN($O$23,$P$23),IF($E34=$O$25,RANDBETWEEN($O$26,$P$26),IF($E34=$O$28,RANDBETWEEN($O$29,$P$29),"0")))))))))) -> 145 | J34: =IF($E34=$O$1,RANDBETWEEN($O$2,$P$2),IF($E34=$O$4,RANDBETWEEN($O$5,$P$5),IF($E34=$O$7,RANDBETWEEN($O$8,$P$8),IF($E34=$O$10,RANDBETWEEN($O$11,$P$11),IF($E34=$O$13,RANDBETWEEN($O$14,$P$14),IF($E34=$O$16,RANDBETWEEN($O$17,$P$17),IF($E34=$O$19,RANDBETWEEN($O$20,$P$20),IF($E34=$O$22,RANDBETWEEN($O$23,$P$23),IF($E34=$O$25,RANDBETWEEN($O$26,$P$26),IF($E34=$O$28,RANDBETWEEN($O$29,$P$29),"0")))))))))) -> 148 | K34: =IF($E34=$O$1,RANDBETWEEN($O$2,$P$2),IF($E34=$O$4,RANDBETWEEN($O$5,$P$5),IF($E34=$O$7,RANDBETWEEN($O$8,$P$8),IF($E34=$O$10,RANDBETWEEN($O$11,$P$11),IF($E34=$O$13,RANDBETWEEN($O$14,$P$14),IF($E34=$O$16,RANDBETWEEN($O$17,$P$17),IF($E34=$O$19,RANDBETWEEN($O$20,$P$20),IF($E34=$O$22,RANDBETWEEN($O$23,$P$23),IF($E34=$O$25,RANDBETWEEN($O$26,$P$26),IF($E34=$O$28,RANDBETWEEN($O$29,$P$29),"0")))))))))) -> 142
A35: ='1 шаблон'!A56 -> Секция 20 | B35: ='1 шаблон'!A57 -> труба | C35: 02+00 | D35: ='1 шаблон'!C56 -> 89 | E35: =$O$1 -> Сталь 20 | F35: =IF($E35=$O$1,RANDBETWEEN($O$2,$P$2),IF($E35=$O$4,RANDBETWEEN($O$5,$P$5),IF($E35=$O$7,RANDBETWEEN($O$8,$P$8),IF($E35=$O$10,RANDBETWEEN($O$11,$P$11),IF($E35=$O$13,RANDBETWEEN($O$14,$P$14),IF($E35=$O$16,RANDBETWEEN($O$17,$P$17),IF($E35=$O$19,RANDBETWEEN($O$20,$P$20),IF($E35=$O$22,RANDBETWEEN($O$23,$P$23),IF($E35=$O$25,RANDBETWEEN($O$26,$P$26),IF($E35=$O$28,RANDBETWEEN($O$29,$P$29),"0")))))))))) -> 139 | G35: =IF($E35=$O$1,RANDBETWEEN($O$2,$P$2),IF($E35=$O$4,RANDBETWEEN($O$5,$P$5),IF($E35=$O$7,RANDBETWEEN($O$8,$P$8),IF($E35=$O$10,RANDBETWEEN($O$11,$P$11),IF($E35=$O$13,RANDBETWEEN($O$14,$P$14),IF($E35=$O$16,RANDBETWEEN($O$17,$P$17),IF($E35=$O$19,RANDBETWEEN($O$20,$P$20),IF($E35=$O$22,RANDBETWEEN($O$23,$P$23),IF($E35=$O$25,RANDBETWEEN($O$26,$P$26),IF($E35=$O$28,RANDBETWEEN($O$29,$P$29),"0")))))))))) -> 151 | H35: =IF($E35=$O$1,RANDBETWEEN($O$2,$P$2),IF($E35=$O$4,RANDBETWEEN($O$5,$P$5),IF($E35=$O$7,RANDBETWEEN($O$8,$P$8),IF($E35=$O$10,RANDBETWEEN($O$11,$P$11),IF($E35=$O$13,RANDBETWEEN($O$14,$P$14),IF($E35=$O$16,RANDBETWEEN($O$17,$P$17),IF($E35=$O$19,RANDBETWEEN($O$20,$P$20),IF($E35=$O$22,RANDBETWEEN($O$23,$P$23),IF($E35=$O$25,RANDBETWEEN($O$26,$P$26),IF($E35=$O$28,RANDBETWEEN($O$29,$P$29),"0")))))))))) -> 152 | I35: =IF($E35=$O$1,RANDBETWEEN($O$2,$P$2),IF($E35=$O$4,RANDBETWEEN($O$5,$P$5),IF($E35=$O$7,RANDBETWEEN($O$8,$P$8),IF($E35=$O$10,RANDBETWEEN($O$11,$P$11),IF($E35=$O$13,RANDBETWEEN($O$14,$P$14),IF($E35=$O$16,RANDBETWEEN($O$17,$P$17),IF($E35=$O$19,RANDBETWEEN($O$20,$P$20),IF($E35=$O$22,RANDBETWEEN($O$23,$P$23),IF($E35=$O$25,RANDBETWEEN($O$26,$P$26),IF($E35=$O$28,RANDBETWEEN($O$29,$P$29),"0")))))))))) -> 149 | J35: =IF($E35=$O$1,RANDBETWEEN($O$2,$P$2),IF($E35=$O$4,RANDBETWEEN($O$5,$P$5),IF($E35=$O$7,RANDBETWEEN($O$8,$P$8),IF($E35=$O$10,RANDBETWEEN($O$11,$P$11),IF($E35=$O$13,RANDBETWEEN($O$14,$P$14),IF($E35=$O$16,RANDBETWEEN($O$17,$P$17),IF($E35=$O$19,RANDBETWEEN($O$20,$P$20),IF($E35=$O$22,RANDBETWEEN($O$23,$P$23),IF($E35=$O$25,RANDBETWEEN($O$26,$P$26),IF($E35=$O$28,RANDBETWEEN($O$29,$P$29),"0")))))))))) -> 138 | K35: =IF($E35=$O$1,RANDBETWEEN($O$2,$P$2),IF($E35=$O$4,RANDBETWEEN($O$5,$P$5),IF($E35=$O$7,RANDBETWEEN($O$8,$P$8),IF($E35=$O$10,RANDBETWEEN($O$11,$P$11),IF($E35=$O$13,RANDBETWEEN($O$14,$P$14),IF($E35=$O$16,RANDBETWEEN($O$17,$P$17),IF($E35=$O$19,RANDBETWEEN($O$20,$P$20),IF($E35=$O$22,RANDBETWEEN($O$23,$P$23),IF($E35=$O$25,RANDBETWEEN($O$26,$P$26),IF($E35=$O$28,RANDBETWEEN($O$29,$P$29),"0")))))))))) -> 144
A36: ='1 шаблон'!A59 -> 0 | B36: ='1 шаблон'!A60 -> 0 | C36: 03+50 | D36: ='1 шаблон'!C59 -> 0 | E36: =$O$1 -> Сталь 20 | F36: =IF($E36=$O$1,RANDBETWEEN($O$2,$P$2),IF($E36=$O$4,RANDBETWEEN($O$5,$P$5),IF($E36=$O$7,RANDBETWEEN($O$8,$P$8),IF($E36=$O$10,RANDBETWEEN($O$11,$P$11),IF($E36=$O$13,RANDBETWEEN($O$14,$P$14),IF($E36=$O$16,RANDBETWEEN($O$17,$P$17),IF($E36=$O$19,RANDBETWEEN($O$20,$P$20),IF($E36=$O$22,RANDBETWEEN($O$23,$P$23),IF($E36=$O$25,RANDBETWEEN($O$26,$P$26),IF($E36=$O$28,RANDBETWEEN($O$29,$P$29),"0")))))))))) -> 141 | G36: =IF($E36=$O$1,RANDBETWEEN($O$2,$P$2),IF($E36=$O$4,RANDBETWEEN($O$5,$P$5),IF($E36=$O$7,RANDBETWEEN($O$8,$P$8),IF($E36=$O$10,RANDBETWEEN($O$11,$P$11),IF($E36=$O$13,RANDBETWEEN($O$14,$P$14),IF($E36=$O$16,RANDBETWEEN($O$17,$P$17),IF($E36=$O$19,RANDBETWEEN($O$20,$P$20),IF($E36=$O$22,RANDBETWEEN($O$23,$P$23),IF($E36=$O$25,RANDBETWEEN($O$26,$P$26),IF($E36=$O$28,RANDBETWEEN($O$29,$P$29),"0")))))))))) -> 152 | H36: =IF($E36=$O$1,RANDBETWEEN($O$2,$P$2),IF($E36=$O$4,RANDBETWEEN($O$5,$P$5),IF($E36=$O$7,RANDBETWEEN($O$8,$P$8),IF($E36=$O$10,RANDBETWEEN($O$11,$P$11),IF($E36=$O$13,RANDBETWEEN($O$14,$P$14),IF($E36=$O$16,RANDBETWEEN($O$17,$P$17),IF($E36=$O$19,RANDBETWEEN($O$20,$P$20),IF($E36=$O$22,RANDBETWEEN($O$23,$P$23),IF($E36=$O$25,RANDBETWEEN($O$26,$P$26),IF($E36=$O$28,RANDBETWEEN($O$29,$P$29),"0")))))))))) -> 148 | I36: =IF($E36=$O$1,RANDBETWEEN($O$2,$P$2),IF($E36=$O$4,RANDBETWEEN($O$5,$P$5),IF($E36=$O$7,RANDBETWEEN($O$8,$P$8),IF($E36=$O$10,RANDBETWEEN($O$11,$P$11),IF($E36=$O$13,RANDBETWEEN($O$14,$P$14),IF($E36=$O$16,RANDBETWEEN($O$17,$P$17),IF($E36=$O$19,RANDBETWEEN($O$20,$P$20),IF($E36=$O$22,RANDBETWEEN($O$23,$P$23),IF($E36=$O$25,RANDBETWEEN($O$26,$P$26),IF($E36=$O$28,RANDBETWEEN($O$29,$P$29),"0")))))))))) -> 137 | J36: =IF($E36=$O$1,RANDBETWEEN($O$2,$P$2),IF($E36=$O$4,RANDBETWEEN($O$5,$P$5),IF($E36=$O$7,RANDBETWEEN($O$8,$P$8),IF($E36=$O$10,RANDBETWEEN($O$11,$P$11),IF($E36=$O$13,RANDBETWEEN($O$14,$P$14),IF($E36=$O$16,RANDBETWEEN($O$17,$P$17),IF($E36=$O$19,RANDBETWEEN($O$20,$P$20),IF($E36=$O$22,RANDBETWEEN($O$23,$P$23),IF($E36=$O$25,RANDBETWEEN($O$26,$P$26),IF($E36=$O$28,RANDBETWEEN($O$29,$P$29),"0")))))))))) -> 137 | K36: =IF($E36=$O$1,RANDBETWEEN($O$2,$P$2),IF($E36=$O$4,RANDBETWEEN($O$5,$P$5),IF($E36=$O$7,RANDBETWEEN($O$8,$P$8),IF($E36=$O$10,RANDBETWEEN($O$11,$P$11),IF($E36=$O$13,RANDBETWEEN($O$14,$P$14),IF($E36=$O$16,RANDBETWEEN($O$17,$P$17),IF($E36=$O$19,RANDBETWEEN($O$20,$P$20),IF($E36=$O$22,RANDBETWEEN($O$23,$P$23),IF($E36=$O$25,RANDBETWEEN($O$26,$P$26),IF($E36=$O$28,RANDBETWEEN($O$29,$P$29),"0")))))))))) -> 138
A37: ='1 шаблон'!A62 -> 0 | B37: ='1 шаблон'!A63 -> 0 | C37: 03+50 | D37: ='1 шаблон'!C62 -> 0 | E37: =$O$1 -> Сталь 20 | F37: =IF($E37=$O$1,RANDBETWEEN($O$2,$P$2),IF($E37=$O$4,RANDBETWEEN($O$5,$P$5),IF($E37=$O$7,RANDBETWEEN($O$8,$P$8),IF($E37=$O$10,RANDBETWEEN($O$11,$P$11),IF($E37=$O$13,RANDBETWEEN($O$14,$P$14),IF($E37=$O$16,RANDBETWEEN($O$17,$P$17),IF($E37=$O$19,RANDBETWEEN($O$20,$P$20),IF($E37=$O$22,RANDBETWEEN($O$23,$P$23),IF($E37=$O$25,RANDBETWEEN($O$26,$P$26),IF($E37=$O$28,RANDBETWEEN($O$29,$P$29),"0")))))))))) -> 148 | G37: =IF($E37=$O$1,RANDBETWEEN($O$2,$P$2),IF($E37=$O$4,RANDBETWEEN($O$5,$P$5),IF($E37=$O$7,RANDBETWEEN($O$8,$P$8),IF($E37=$O$10,RANDBETWEEN($O$11,$P$11),IF($E37=$O$13,RANDBETWEEN($O$14,$P$14),IF($E37=$O$16,RANDBETWEEN($O$17,$P$17),IF($E37=$O$19,RANDBETWEEN($O$20,$P$20),IF($E37=$O$22,RANDBETWEEN($O$23,$P$23),IF($E37=$O$25,RANDBETWEEN($O$26,$P$26),IF($E37=$O$28,RANDBETWEEN($O$29,$P$29),"0")))))))))) -> 147 | H37: =IF($E37=$O$1,RANDBETWEEN($O$2,$P$2),IF($E37=$O$4,RANDBETWEEN($O$5,$P$5),IF($E37=$O$7,RANDBETWEEN($O$8,$P$8),IF($E37=$O$10,RANDBETWEEN($O$11,$P$11),IF($E37=$O$13,RANDBETWEEN($O$14,$P$14),IF($E37=$O$16,RANDBETWEEN($O$17,$P$17),IF($E37=$O$19,RANDBETWEEN($O$20,$P$20),IF($E37=$O$22,RANDBETWEEN($O$23,$P$23),IF($E37=$O$25,RANDBETWEEN($O$26,$P$26),IF($E37=$O$28,RANDBETWEEN($O$29,$P$29),"0")))))))))) -> 144 | I37: =IF($E37=$O$1,RANDBETWEEN($O$2,$P$2),IF($E37=$O$4,RANDBETWEEN($O$5,$P$5),IF($E37=$O$7,RANDBETWEEN($O$8,$P$8),IF($E37=$O$10,RANDBETWEEN($O$11,$P$11),IF($E37=$O$13,RANDBETWEEN($O$14,$P$14),IF($E37=$O$16,RANDBETWEEN($O$17,$P$17),IF($E37=$O$19,RANDBETWEEN($O$20,$P$20),IF($E37=$O$22,RANDBETWEEN($O$23,$P$23),IF($E37=$O$25,RANDBETWEEN($O$26,$P$26),IF($E37=$O$28,RANDBETWEEN($O$29,$P$29),"0")))))))))) -> 146 | J37: =IF($E37=$O$1,RANDBETWEEN($O$2,$P$2),IF($E37=$O$4,RANDBETWEEN($O$5,$P$5),IF($E37=$O$7,RANDBETWEEN($O$8,$P$8),IF($E37=$O$10,RANDBETWEEN($O$11,$P$11),IF($E37=$O$13,RANDBETWEEN($O$14,$P$14),IF($E37=$O$16,RANDBETWEEN($O$17,$P$17),IF($E37=$O$19,RANDBETWEEN($O$20,$P$20),IF($E37=$O$22,RANDBETWEEN($O$23,$P$23),IF($E37=$O$25,RANDBETWEEN($O$26,$P$26),IF($E37=$O$28,RANDBETWEEN($O$29,$P$29),"0")))))))))) -> 149 | K37: =IF($E37=$O$1,RANDBETWEEN($O$2,$P$2),IF($E37=$O$4,RANDBETWEEN($O$5,$P$5),IF($E37=$O$7,RANDBETWEEN($O$8,$P$8),IF($E37=$O$10,RANDBETWEEN($O$11,$P$11),IF($E37=$O$13,RANDBETWEEN($O$14,$P$14),IF($E37=$O$16,RANDBETWEEN($O$17,$P$17),IF($E37=$O$19,RANDBETWEEN($O$20,$P$20),IF($E37=$O$22,RANDBETWEEN($O$23,$P$23),IF($E37=$O$25,RANDBETWEEN($O$26,$P$26),IF($E37=$O$28,RANDBETWEEN($O$29,$P$29),"0")))))))))) -> 141
A38: ='1 шаблон'!A65 -> 0 | B38: ='1 шаблон'!A66 -> 0 | C38: 03+50 | D38: ='1 шаблон'!C65 -> 0 | E38: =$O$1 -> Сталь 20 | F38: =IF($E38=$O$1,RANDBETWEEN($O$2,$P$2),IF($E38=$O$4,RANDBETWEEN($O$5,$P$5),IF($E38=$O$7,RANDBETWEEN($O$8,$P$8),IF($E38=$O$10,RANDBETWEEN($O$11,$P$11),IF($E38=$O$13,RANDBETWEEN($O$14,$P$14),IF($E38=$O$16,RANDBETWEEN($O$17,$P$17),IF($E38=$O$19,RANDBETWEEN($O$20,$P$20),IF($E38=$O$22,RANDBETWEEN($O$23,$P$23),IF($E38=$O$25,RANDBETWEEN($O$26,$P$26),IF($E38=$O$28,RANDBETWEEN($O$29,$P$29),"0")))))))))) -> 149 | G38: =IF($E38=$O$1,RANDBETWEEN($O$2,$P$2),IF($E38=$O$4,RANDBETWEEN($O$5,$P$5),IF($E38=$O$7,RANDBETWEEN($O$8,$P$8),IF($E38=$O$10,RANDBETWEEN($O$11,$P$11),IF($E38=$O$13,RANDBETWEEN($O$14,$P$14),IF($E38=$O$16,RANDBETWEEN($O$17,$P$17),IF($E38=$O$19,RANDBETWEEN($O$20,$P$20),IF($E38=$O$22,RANDBETWEEN($O$23,$P$23),IF($E38=$O$25,RANDBETWEEN($O$26,$P$26),IF($E38=$O$28,RANDBETWEEN($O$29,$P$29),"0")))))))))) -> 143 | H38: =IF($E38=$O$1,RANDBETWEEN($O$2,$P$2),IF($E38=$O$4,RANDBETWEEN($O$5,$P$5),IF($E38=$O$7,RANDBETWEEN($O$8,$P$8),IF($E38=$O$10,RANDBETWEEN($O$11,$P$11),IF($E38=$O$13,RANDBETWEEN($O$14,$P$14),IF($E38=$O$16,RANDBETWEEN($O$17,$P$17),IF($E38=$O$19,RANDBETWEEN($O$20,$P$20),IF($E38=$O$22,RANDBETWEEN($O$23,$P$23),IF($E38=$O$25,RANDBETWEEN($O$26,$P$26),IF($E38=$O$28,RANDBETWEEN($O$29,$P$29),"0")))))))))) -> 152 | I38: =IF($E38=$O$1,RANDBETWEEN($O$2,$P$2),IF($E38=$O$4,RANDBETWEEN($O$5,$P$5),IF($E38=$O$7,RANDBETWEEN($O$8,$P$8),IF($E38=$O$10,RANDBETWEEN($O$11,$P$11),IF($E38=$O$13,RANDBETWEEN($O$14,$P$14),IF($E38=$O$16,RANDBETWEEN($O$17,$P$17),IF($E38=$O$19,RANDBETWEEN($O$20,$P$20),IF($E38=$O$22,RANDBETWEEN($O$23,$P$23),IF($E38=$O$25,RANDBETWEEN($O$26,$P$26),IF($E38=$O$28,RANDBETWEEN($O$29,$P$29),"0")))))))))) -> 142 | J38: =IF($E38=$O$1,RANDBETWEEN($O$2,$P$2),IF($E38=$O$4,RANDBETWEEN($O$5,$P$5),IF($E38=$O$7,RANDBETWEEN($O$8,$P$8),IF($E38=$O$10,RANDBETWEEN($O$11,$P$11),IF($E38=$O$13,RANDBETWEEN($O$14,$P$14),IF($E38=$O$16,RANDBETWEEN($O$17,$P$17),IF($E38=$O$19,RANDBETWEEN($O$20,$P$20),IF($E38=$O$22,RANDBETWEEN($O$23,$P$23),IF($E38=$O$25,RANDBETWEEN($O$26,$P$26),IF($E38=$O$28,RANDBETWEEN($O$29,$P$29),"0")))))))))) -> 149 | K38: =IF($E38=$O$1,RANDBETWEEN($O$2,$P$2),IF($E38=$O$4,RANDBETWEEN($O$5,$P$5),IF($E38=$O$7,RANDBETWEEN($O$8,$P$8),IF($E38=$O$10,RANDBETWEEN($O$11,$P$11),IF($E38=$O$13,RANDBETWEEN($O$14,$P$14),IF($E38=$O$16,RANDBETWEEN($O$17,$P$17),IF($E38=$O$19,RANDBETWEEN($O$20,$P$20),IF($E38=$O$22,RANDBETWEEN($O$23,$P$23),IF($E38=$O$25,RANDBETWEEN($O$26,$P$26),IF($E38=$O$28,RANDBETWEEN($O$29,$P$29),"0")))))))))) -> 152
A39: ='1 шаблон'!A68 -> 0 | B39: ='1 шаблон'!A69 -> 0 | C39: 03+50 | D39: ='1 шаблон'!C68 -> 0 | E39: =$O$1 -> Сталь 20 | F39: =IF($E39=$O$1,RANDBETWEEN($O$2,$P$2),IF($E39=$O$4,RANDBETWEEN($O$5,$P$5),IF($E39=$O$7,RANDBETWEEN($O$8,$P$8),IF($E39=$O$10,RANDBETWEEN($O$11,$P$11),IF($E39=$O$13,RANDBETWEEN($O$14,$P$14),IF($E39=$O$16,RANDBETWEEN($O$17,$P$17),IF($E39=$O$19,RANDBETWEEN($O$20,$P$20),IF($E39=$O$22,RANDBETWEEN($O$23,$P$23),IF($E39=$O$25,RANDBETWEEN($O$26,$P$26),IF($E39=$O$28,RANDBETWEEN($O$29,$P$29),"0")))))))))) -> 137 | G39: =IF($E39=$O$1,RANDBETWEEN($O$2,$P$2),IF($E39=$O$4,RANDBETWEEN($O$5,$P$5),IF($E39=$O$7,RANDBETWEEN($O$8,$P$8),IF($E39=$O$10,RANDBETWEEN($O$11,$P$11),IF($E39=$O$13,RANDBETWEEN($O$14,$P$14),IF($E39=$O$16,RANDBETWEEN($O$17,$P$17),IF($E39=$O$19,RANDBETWEEN($O$20,$P$20),IF($E39=$O$22,RANDBETWEEN($O$23,$P$23),IF($E39=$O$25,RANDBETWEEN($O$26,$P$26),IF($E39=$O$28,RANDBETWEEN($O$29,$P$29),"0")))))))))) -> 138 | H39: =IF($E39=$O$1,RANDBETWEEN($O$2,$P$2),IF($E39=$O$4,RANDBETWEEN($O$5,$P$5),IF($E39=$O$7,RANDBETWEEN($O$8,$P$8),IF($E39=$O$10,RANDBETWEEN($O$11,$P$11),IF($E39=$O$13,RANDBETWEEN($O$14,$P$14),IF($E39=$O$16,RANDBETWEEN($O$17,$P$17),IF($E39=$O$19,RANDBETWEEN($O$20,$P$20),IF($E39=$O$22,RANDBETWEEN($O$23,$P$23),IF($E39=$O$25,RANDBETWEEN($O$26,$P$26),IF($E39=$O$28,RANDBETWEEN($O$29,$P$29),"0")))))))))) -> 149 | I39: =IF($E39=$O$1,RANDBETWEEN($O$2,$P$2),IF($E39=$O$4,RANDBETWEEN($O$5,$P$5),IF($E39=$O$7,RANDBETWEEN($O$8,$P$8),IF($E39=$O$10,RANDBETWEEN($O$11,$P$11),IF($E39=$O$13,RANDBETWEEN($O$14,$P$14),IF($E39=$O$16,RANDBETWEEN($O$17,$P$17),IF($E39=$O$19,RANDBETWEEN($O$20,$P$20),IF($E39=$O$22,RANDBETWEEN($O$23,$P$23),IF($E39=$O$25,RANDBETWEEN($O$26,$P$26),IF($E39=$O$28,RANDBETWEEN($O$29,$P$29),"0")))))))))) -> 151 | J39: =IF($E39=$O$1,RANDBETWEEN($O$2,$P$2),IF($E39=$O$4,RANDBETWEEN($O$5,$P$5),IF($E39=$O$7,RANDBETWEEN($O$8,$P$8),IF($E39=$O$10,RANDBETWEEN($O$11,$P$11),IF($E39=$O$13,RANDBETWEEN($O$14,$P$14),IF($E39=$O$16,RANDBETWEEN($O$17,$P$17),IF($E39=$O$19,RANDBETWEEN($O$20,$P$20),IF($E39=$O$22,RANDBETWEEN($O$23,$P$23),IF($E39=$O$25,RANDBETWEEN($O$26,$P$26),IF($E39=$O$28,RANDBETWEEN($O$29,$P$29),"0")))))))))) -> 140 | K39: =IF($E39=$O$1,RANDBETWEEN($O$2,$P$2),IF($E39=$O$4,RANDBETWEEN($O$5,$P$5),IF($E39=$O$7,RANDBETWEEN($O$8,$P$8),IF($E39=$O$10,RANDBETWEEN($O$11,$P$11),IF($E39=$O$13,RANDBETWEEN($O$14,$P$14),IF($E39=$O$16,RANDBETWEEN($O$17,$P$17),IF($E39=$O$19,RANDBETWEEN($O$20,$P$20),IF($E39=$O$22,RANDBETWEEN($O$23,$P$23),IF($E39=$O$25,RANDBETWEEN($O$26,$P$26),IF($E39=$O$28,RANDBETWEEN($O$29,$P$29),"0")))))))))) -> 137
A40: ='1 шаблон'!A71 -> 0 | B40: ='1 шаблон'!A72 -> 0 | C40: ='1 шаблон'!B71 -> 0 | D40: ='1 шаблон'!C71 -> 0 | E40: =$O$1 -> Сталь 20 | F40: =IF($E40=$O$1,RANDBETWEEN($O$2,$P$2),IF($E40=$O$4,RANDBETWEEN($O$5,$P$5),IF($E40=$O$7,RANDBETWEEN($O$8,$P$8),IF($E40=$O$10,RANDBETWEEN($O$11,$P$11),IF($E40=$O$13,RANDBETWEEN($O$14,$P$14),IF($E40=$O$16,RANDBETWEEN($O$17,$P$17),IF($E40=$O$19,RANDBETWEEN($O$20,$P$20),IF($E40=$O$22,RANDBETWEEN($O$23,$P$23),IF($E40=$O$25,RANDBETWEEN($O$26,$P$26),IF($E40=$O$28,RANDBETWEEN($O$29,$P$29),"0")))))))))) -> 138 | G40: =IF($E40=$O$1,RANDBETWEEN($O$2,$P$2),IF($E40=$O$4,RANDBETWEEN($O$5,$P$5),IF($E40=$O$7,RANDBETWEEN($O$8,$P$8),IF($E40=$O$10,RANDBETWEEN($O$11,$P$11),IF($E40=$O$13,RANDBETWEEN($O$14,$P$14),IF($E40=$O$16,RANDBETWEEN($O$17,$P$17),IF($E40=$O$19,RANDBETWEEN($O$20,$P$20),IF($E40=$O$22,RANDBETWEEN($O$23,$P$23),IF($E40=$O$25,RANDBETWEEN($O$26,$P$26),IF($E40=$O$28,RANDBETWEEN($O$29,$P$29),"0")))))))))) -> 147 | H40: =IF($E40=$O$1,RANDBETWEEN($O$2,$P$2),IF($E40=$O$4,RANDBETWEEN($O$5,$P$5),IF($E40=$O$7,RANDBETWEEN($O$8,$P$8),IF($E40=$O$10,RANDBETWEEN($O$11,$P$11),IF($E40=$O$13,RANDBETWEEN($O$14,$P$14),IF($E40=$O$16,RANDBETWEEN($O$17,$P$17),IF($E40=$O$19,RANDBETWEEN($O$20,$P$20),IF($E40=$O$22,RANDBETWEEN($O$23,$P$23),IF($E40=$O$25,RANDBETWEEN($O$26,$P$26),IF($E40=$O$28,RANDBETWEEN($O$29,$P$29),"0")))))))))) -> 139 | I40: =IF($E40=$O$1,RANDBETWEEN($O$2,$P$2),IF($E40=$O$4,RANDBETWEEN($O$5,$P$5),IF($E40=$O$7,RANDBETWEEN($O$8,$P$8),IF($E40=$O$10,RANDBETWEEN($O$11,$P$11),IF($E40=$O$13,RANDBETWEEN($O$14,$P$14),IF($E40=$O$16,RANDBETWEEN($O$17,$P$17),IF($E40=$O$19,RANDBETWEEN($O$20,$P$20),IF($E40=$O$22,RANDBETWEEN($O$23,$P$23),IF($E40=$O$25,RANDBETWEEN($O$26,$P$26),IF($E40=$O$28,RANDBETWEEN($O$29,$P$29),"0")))))))))) -> 151 | J40: =IF($E40=$O$1,RANDBETWEEN($O$2,$P$2),IF($E40=$O$4,RANDBETWEEN($O$5,$P$5),IF($E40=$O$7,RANDBETWEEN($O$8,$P$8),IF($E40=$O$10,RANDBETWEEN($O$11,$P$11),IF($E40=$O$13,RANDBETWEEN($O$14,$P$14),IF($E40=$O$16,RANDBETWEEN($O$17,$P$17),IF($E40=$O$19,RANDBETWEEN($O$20,$P$20),IF($E40=$O$22,RANDBETWEEN($O$23,$P$23),IF($E40=$O$25,RANDBETWEEN($O$26,$P$26),IF($E40=$O$28,RANDBETWEEN($O$29,$P$29),"0")))))))))) -> 148 | K40: =IF($E40=$O$1,RANDBETWEEN($O$2,$P$2),IF($E40=$O$4,RANDBETWEEN($O$5,$P$5),IF($E40=$O$7,RANDBETWEEN($O$8,$P$8),IF($E40=$O$10,RANDBETWEEN($O$11,$P$11),IF($E40=$O$13,RANDBETWEEN($O$14,$P$14),IF($E40=$O$16,RANDBETWEEN($O$17,$P$17),IF($E40=$O$19,RANDBETWEEN($O$20,$P$20),IF($E40=$O$22,RANDBETWEEN($O$23,$P$23),IF($E40=$O$25,RANDBETWEEN($O$26,$P$26),IF($E40=$O$28,RANDBETWEEN($O$29,$P$29),"0")))))))))) -> 137
A41: ='1 шаблон'!A74 -> 0 | B41: ='1 шаблон'!A75 -> 0 | C41: ='1 шаблон'!B74 -> 0 | D41: ='1 шаблон'!C74 -> 0 | E41: =$O$1 -> Сталь 20 | F41: =IF($E41=$O$1,RANDBETWEEN($O$2,$P$2),IF($E41=$O$4,RANDBETWEEN($O$5,$P$5),IF($E41=$O$7,RANDBETWEEN($O$8,$P$8),IF($E41=$O$10,RANDBETWEEN($O$11,$P$11),IF($E41=$O$13,RANDBETWEEN($O$14,$P$14),IF($E41=$O$16,RANDBETWEEN($O$17,$P$17),IF($E41=$O$19,RANDBETWEEN($O$20,$P$20),IF($E41=$O$22,RANDBETWEEN($O$23,$P$23),IF($E41=$O$25,RANDBETWEEN($O$26,$P$26),IF($E41=$O$28,RANDBETWEEN($O$29,$P$29),"0")))))))))) -> 142 | G41: =IF($E41=$O$1,RANDBETWEEN($O$2,$P$2),IF($E41=$O$4,RANDBETWEEN($O$5,$P$5),IF($E41=$O$7,RANDBETWEEN($O$8,$P$8),IF($E41=$O$10,RANDBETWEEN($O$11,$P$11),IF($E41=$O$13,RANDBETWEEN($O$14,$P$14),IF($E41=$O$16,RANDBETWEEN($O$17,$P$17),IF($E41=$O$19,RANDBETWEEN($O$20,$P$20),IF($E41=$O$22,RANDBETWEEN($O$23,$P$23),IF($E41=$O$25,RANDBETWEEN($O$26,$P$26),IF($E41=$O$28,RANDBETWEEN($O$29,$P$29),"0")))))))))) -> 141 | H41: =IF($E41=$O$1,RANDBETWEEN($O$2,$P$2),IF($E41=$O$4,RANDBETWEEN($O$5,$P$5),IF($E41=$O$7,RANDBETWEEN($O$8,$P$8),IF($E41=$O$10,RANDBETWEEN($O$11,$P$11),IF($E41=$O$13,RANDBETWEEN($O$14,$P$14),IF($E41=$O$16,RANDBETWEEN($O$17,$P$17),IF($E41=$O$19,RANDBETWEEN($O$20,$P$20),IF($E41=$O$22,RANDBETWEEN($O$23,$P$23),IF($E41=$O$25,RANDBETWEEN($O$26,$P$26),IF($E41=$O$28,RANDBETWEEN($O$29,$P$29),"0")))))))))) -> 138 | I41: =IF($E41=$O$1,RANDBETWEEN($O$2,$P$2),IF($E41=$O$4,RANDBETWEEN($O$5,$P$5),IF($E41=$O$7,RANDBETWEEN($O$8,$P$8),IF($E41=$O$10,RANDBETWEEN($O$11,$P$11),IF($E41=$O$13,RANDBETWEEN($O$14,$P$14),IF($E41=$O$16,RANDBETWEEN($O$17,$P$17),IF($E41=$O$19,RANDBETWEEN($O$20,$P$20),IF($E41=$O$22,RANDBETWEEN($O$23,$P$23),IF($E41=$O$25,RANDBETWEEN($O$26,$P$26),IF($E41=$O$28,RANDBETWEEN($O$29,$P$29),"0")))))))))) -> 137 | J41: =IF($E41=$O$1,RANDBETWEEN($O$2,$P$2),IF($E41=$O$4,RANDBETWEEN($O$5,$P$5),IF($E41=$O$7,RANDBETWEEN($O$8,$P$8),IF($E41=$O$10,RANDBETWEEN($O$11,$P$11),IF($E41=$O$13,RANDBETWEEN($O$14,$P$14),IF($E41=$O$16,RANDBETWEEN($O$17,$P$17),IF($E41=$O$19,RANDBETWEEN($O$20,$P$20),IF($E41=$O$22,RANDBETWEEN($O$23,$P$23),IF($E41=$O$25,RANDBETWEEN($O$26,$P$26),IF($E41=$O$28,RANDBETWEEN($O$29,$P$29),"0")))))))))) -> 151 | K41: =IF($E41=$O$1,RANDBETWEEN($O$2,$P$2),IF($E41=$O$4,RANDBETWEEN($O$5,$P$5),IF($E41=$O$7,RANDBETWEEN($O$8,$P$8),IF($E41=$O$10,RANDBETWEEN($O$11,$P$11),IF($E41=$O$13,RANDBETWEEN($O$14,$P$14),IF($E41=$O$16,RANDBETWEEN($O$17,$P$17),IF($E41=$O$19,RANDBETWEEN($O$20,$P$20),IF($E41=$O$22,RANDBETWEEN($O$23,$P$23),IF($E41=$O$25,RANDBETWEEN($O$26,$P$26),IF($E41=$O$28,RANDBETWEEN($O$29,$P$29),"0")))))))))) -> 149
...

Sheet 2 Приложение 13 (чистовик)
A1: Для ОК, ЗКЛ, ЗДШ | J1: Результат | O1: Сталь 20
A2: № секции | B2: наим секции | C2: Пикет | D2: Диаметр, мм | E2: Марка стали | F2: Результаты измерений: НВ | J2: Мин | K2: =SUBTOTAL(5,F5:I25) -> 144 | O2: 137 | P2: 153
D3: мм | E3: стали | F3: т.1 | G3: т.2 | H3: т.3 | I3: т.4 | J3: Макс | K3: =SUBTOTAL(4,F5:I25) -> 151
A4: 1 | B4: 1 | C4: 2 | D4: 3 | E4: 4 | F4: 5 | G4: 6 | H4: 7 | I4: 8 | O4: Сталь 10
A5: ='1 шаблон'!A5 -> Секция 30 | B5: ='1 шаблон'!A6 -> ЗМС | C5: ='1 шаблон'!B5 -> 00+20 | D5: ='1 шаблон'!C5 -> 65 | E5: ='2 Приложение 13'!E5 -> Сталь 20 | F5: 146 | G5: 150 | H5: 151 | I5: 144 | O5: 125 | P5: 143
A6: ='1 шаблон'!A7 -> 0 | B6: ='1 шаблон'!A8 -> 0 | C6: ='1 шаблон'!B7 -> 0 | D6: ='1 шаблон'!C7 -> 0 | E6: ='2 Приложение 13'!E6 -> Сталь 20
A7: ='1 шаблон'!A9 -> 0 | B7: ='1 шаблон'!A10 -> 0 | C7: ='1 шаблон'!B9 -> 0 | D7: ='1 шаблон'!C9 -> 0 | E7: ='2 Приложение 13'!E7 -> Сталь 20Л | O7: Сталь 25Л
A8: ='1 шаблон'!A11 -> 0 | B8: ='1 шаблон'!A12 -> 0 | C8: ='1 шаблон'!B11 -> 0 | D8: ='1 шаблон'!C11 -> 0 | E8: ='2 Приложение 13'!E8 -> Сталь 20Л | O8: 121 | P8: 151
A9: ='1 шаблон'!A13 -> 0 | B9: ='1 шаблон'!A14 -> 0 | C9: ='1 шаблон'!B13 -> 0 | D9: ='1 шаблон'!C13 -> 0 | E9: ='2 Приложение 13'!E9 -> Сталь 20Л
A10: ='1 шаблон'!A15 -> 0 | B10: ='1 шаблон'!A16 -> 0 | C10: ='1 шаблон'!B15 -> 0 | D10: ='1 шаблон'!C15 -> 0 | E10: ='2 Приложение 13'!E10 -> Сталь 20 | O10: Сталь 20Л | Q10: (если Д<100)
A11: ='1 шаблон'!A17 -> 0 | B11: ='1 шаблон'!A18 -> 0 | C11: ='1 шаблон'!B17 -> 0 | D11: ='1 шаблон'!C17 -> 0 | E11: ='2 Приложение 13'!E11 -> Сталь 20 | O11: 116 | P11: 144
A12: ='1 шаблон'!A19 -> 0 | B12: ='1 шаблон'!A20 -> 0 | C12: ='1 шаблон'!B19 -> 0 | D12: ='1 шаблон'!C19 -> 0 | E12: ='2 Приложение 13'!E12 -> Сталь 20
A13: ='1 шаблон'!A21 -> 0 | B13: ='1 шаблон'!A22 -> 0 | C13: ='1 шаблон'!B21 -> 0 | D13: ='1 шаблон'!C21 -> 0 | E13: ='2 Приложение 13'!E13 -> Сталь 20 | O13: Сталь 20Л | Q13: (если Д>100)
A14: ='1 шаблон'!A23 -> 0 | B14: ='1 шаблон'!A24 -> 0 | C14: ='1 шаблон'!B23 -> 0 | D14: ='1 шаблон'!C23 -> 0 | E14: ='2 Приложение 13'!E14 -> Сталь 20 | O14: 111 | P14: 156
A15: ='1 шаблон'!A25 -> 0 | B15: ='1 шаблон'!A26 -> 0 | C15: ='1 шаблон'!B25 -> 0 | D15: ='1 шаблон'!C25 -> 0 | E15: ='2 Приложение 13'!E15 -> Сталь 20
A16: ='1 шаблон'!A27 -> 0 | B16: ='1 шаблон'!A28 -> 0 | C16: ='1 шаблон'!B27 -> 0 | D16: ='1 шаблон'!C27 -> 0 | E16: ='2 Приложение 13'!E16 -> Сталь 20 | O16: Сталь 3сп
A17: ='1 шаблон'!A29 -> 0 | B17: ='1 шаблон'!A30 -> 0 | C17: ='1 шаблон'!B29 -> 0 | D17: ='1 шаблон'!C29 -> 0 | E17: ='2 Приложение 13'!E17 -> Сталь 20Л | O17: 111 | P17: 156
A18: ='1 шаблон'!A31 -> 0 | B18: ='1 шаблон'!A32 -> 0 | C18: ='1 шаблон'!B31 -> 0 | D18: ='1 шаблон'!C31 -> 0 | E18: ='2 Приложение 13'!E18 -> Сталь 20Л
A19: ='1 шаблон'!A33 -> 0 | B19: ='1 шаблон'!A34 -> 0 | C19: ='1 шаблон'!B33 -> 0 | D19: ='1 шаблон'!C33 -> 0 | E19: ='2 Приложение 13'!E19 -> Сталь 20Л | O19: Сталь 09Г2С
A20: ='1 шаблон'!A35 -> 0 | B20: ='1 шаблон'!A36 -> 0 | C20: ='1 шаблон'!B35 -> 0 | D20: ='1 шаблон'!C35 -> 0 | E20: ='2 Приложение 13'!E20 -> Сталь 20Л | O20: 135 | P20: 152
A21: ='1 шаблон'!A37 -> 0 | B21: ='1 шаблон'!A38 -> 0 | C21: ='1 шаблон'!B37 -> 0 | D21: ='1 шаблон'!C37 -> 0 | E21: ='2 Приложение 13'!E21 -> Сталь 20Л
O22: Сталь 15
O23: 137 | P23: 148
O25: Сталь 25
O26: 162 | P26: 170
A28: Если на трубе разные стали, то для определния мин и мак сначения для каждой стали по фильтру ставим нужную сталь, и в результатах смотрим миним и макс значение | O28: Сталь 30ХМ
O29: 200 | P29: 250
A30: Трубопровод | L30: Результат
A31: № секции | B31: наим секции | C31: Пикет | D31: Диаметр, мм | E31: Марка стали | F31: Результаты измерений: НВ | L31: Мин | M31: =SUBTOTAL(5,F34:K245) -> 137
D32: мм | E32: стали | F32: т.1 | G32: т.2 | H32: т.3 | I32: т.4 | J32: т.5 | K32: т.6 | L32: Макс | M32: =SUBTOTAL(4,F34:K245) -> 150
A33: 1 | B33: 1 | C33: 2 | D33: 3 | E33: 4 | F33: 5 | G33: 6 | H33: 7 | I33: 8 | J33: 9 | K33: 10 | L33: Минимальная на секции
A34: ='1 шаблон'!A53 -> Секция 10 | B34: ='1 шаблон'!A54 -> Шурф № 1 | C34: ='1 шаблон'!B53 -> 00+10 | D34: ='1 шаблон'!C53 -> 89 | E34: ='2 Приложение 13'!E34 -> Сталь 20 | F34: 148 | G34: 143 | H34: 147 | I34: 147 | J34: 137 | K34: 137 | L34: =MIN(F34:K34) -> 137
A35: ='1 шаблон'!A56 -> Секция 20 | B35: ='1 шаблон'!A57 -> труба | C35: ='1 шаблон'!B56 -> 00+20 | D35: ='1 шаблон'!C56 -> 89 | E35: ='2 Приложение 13'!E35 -> Сталь 20 | F35: 148 | G35: 147 | H35: 150 | I35: 146 | J35: 145 | K35: 150 | L35: =MIN(F35:K35) -> 145
A36: ='1 шаблон'!A59 -> 0 | B36: ='1 шаблон'!A60 -> 0 | C36: ='1 шаблон'!B59 -> 0 | D36: ='1 шаблон'!C59 -> 0 | E36: ='2 Приложение 13'!E36 -> Сталь 20 | L36: =MIN(F36:K36) -> 0
A37: ='1 шаблон'!A62 -> 0 | B37: ='1 шаблон'!A63 -> 0 | C37: ='1 шаблон'!B62 -> 0 | D37: ='1 шаблон'!C62 -> 0 | E37: ='2 Приложение 13'!E37 -> Сталь 20 | L37: =MIN(F37:K37) -> 0
A38: ='1 шаблон'!A65 -> 0 | B38: ='1 шаблон'!A66 -> 0 | C38: ='1 шаблон'!B65 -> 0 | D38: ='1 шаблон'!C65 -> 0 | E38: ='2 Приложение 13'!E38 -> Сталь 20 | L38: =MIN(F38:K38) -> 0
A39: ='1 шаблон'!A68 -> 0 | B39: ='1 шаблон'!A69 -> 0 | C39: ='1 шаблон'!B68 -> 0 | D39: ='1 шаблон'!C68 -> 0 | E39: ='2 Приложение 13'!E39 -> Сталь 20 | L39: =MIN(F39:K39) -> 0
A40: ='1 шаблон'!A71 -> 0 | B40: ='1 шаблон'!A72 -> 0 | C40: ='1 шаблон'!B71 -> 0 | D40: ='1 шаблон'!C71 -> 0 | E40: ='2 Приложение 13'!E40 -> Сталь 20 | L40: =MIN(F40:K40) -> 0
A41: ='1 шаблон'!A74 -> 0 | B41: ='1 шаблон'!A75 -> 0 | C41: ='1 шаблон'!B74 -> 0 | D41: ='1 шаблон'!C74 -> 0 | E41: ='2 Приложение 13'!E41 -> Сталь 20 | L41: =MIN(F41:K41) -> 0
A42: ='1 шаблон'!A77 -> 0 | B42: ='1 шаблон'!A78 -> 0 | C42: ='1 шаблон'!B77 -> 0 | D42: ='1 шаблон'!C77 -> 0 | E42: ='2 Приложение 13'!E42 -> Сталь 20 | L42: =MIN(F42:K42) -> 0
...

Sheet 3 Прил 12 (толщинометрия)
C1: Таблица для ОК и ЗКЛ
C2: № | D2: Пикет | E2: Ду, мм | F2: Sном, | G2: Sотбр, | H2: Sмин, | I2: Результаты измерений: Нфак., мм | N2: Sмин вписывается вручную
F3: мм | G3: мм | H3: мм | I3: т.1 | J3: т.2 | K3: т.3 | L3: т.4
C4: 1 | D4: 2 | E4: 3 | F4: 4 | G4: 4 | H4: 5 | I4: 6 | J4: 7 | K4: 8 | L4: 9 | N4: Результаты измерений рандомно заполняются значениями
C5: ='1 шаблон'!A6 -> ЗМС | D5: ='1 шаблон'!B5 -> 00+20 | E5: ='1 шаблон'!C5 -> 65 | F5: ='1 шаблон'!D5 -> 16 | G5: =VLOOKUP(E5,'Приложение 15'!$AG$284:$AJ$303,4,0) -> #N/A | H5: 15.9 | I5: =H5 -> 15.9 | J5: =RANDBETWEEN($H5*10,$F5*10)/10 -> 15.9 | K5: =RANDBETWEEN($H5*10,$F5*10)/10 -> 16 | L5: =RANDBETWEEN($H5*10,$F5*10)/10 -> 15.9 | N5: Рандомные значения измерений нужно скопировать и вставить только значения на лист "чистовик+вывод"
C6: ='1 шаблон'!A8 -> 0 | D6: ='1 шаблон'!B7 -> 0 | E6: ='1 шаблон'!C7 -> 0 | F6: ='1 шаблон'!D7 -> 0 | G6: =VLOOKUP(E6,'Приложение 15'!$AG$284:$AJ$303,4,0) -> #N/A | H6: 16.9 | I6: =H6 -> 16.9 | J6: =RANDBETWEEN($H6*10,$F6*10)/10 -> #NUM! | K6: =RANDBETWEEN($H6*10,$F6*10)/10 -> #NUM! | L6: =RANDBETWEEN($H6*10,$F6*10)/10 -> #NUM! | N6: Это делается для того чтобы оставить только значения без формулы случайного числа, т.к. при каждом нажатии enter значения меняются
C7: ='1 шаблон'!A10 -> 0 | D7: ='1 шаблон'!B9 -> 0 | E7: ='1 шаблон'!C9 -> 0 | F7: ='1 шаблон'!D9 -> 0 | G7: =VLOOKUP(E7,'Приложение 15'!$AG$284:$AJ$303,4,0) -> #N/A | H7: 13.9 | I7: =H7 -> 13.9 | J7: =RANDBETWEEN($H7*10,$F7*10)/10 -> #NUM! | K7: =RANDBETWEEN($H7*10,$F7*10)/10 -> #NUM! | L7: =RANDBETWEEN($H7*10,$F7*10)/10 -> #NUM!
C8: ='1 шаблон'!A12 -> 0 | D8: ='1 шаблон'!B11 -> 0 | E8: ='1 шаблон'!C11 -> 0 | F8: ='1 шаблон'!D11 -> 0 | G8: =VLOOKUP(E8,'Приложение 15'!$AG$284:$AJ$303,4,0) -> #N/A | H8: 13.9 | I8: =H8 -> 13.9 | J8: =RANDBETWEEN($H8*10,$F8*10)/10 -> #NUM! | K8: =RANDBETWEEN($H8*10,$F8*10)/10 -> #NUM! | L8: =RANDBETWEEN($H8*10,$F8*10)/10 -> #NUM!
C9: ='1 шаблон'!A14 -> 0 | D9: ='1 шаблон'!B13 -> 0 | E9: ='1 шаблон'!C13 -> 0 | F9: ='1 шаблон'!D13 -> 0 | G9: =VLOOKUP(E9,'Приложение 15'!$AG$284:$AJ$303,4,0) -> #N/A | H9: 28.2 | I9: =H9 -> 28.2 | J9: =RANDBETWEEN($H9*10,$F9*10)/10 -> #NUM! | K9: =RANDBETWEEN($H9*10,$F9*10)/10 -> #NUM! | L9: =RANDBETWEEN($H9*10,$F9*10)/10 -> #NUM! | N9: шапка выделеная таким цветом заполняется автоматически
C10: ='1 шаблон'!A16 -> 0 | D10: ='1 шаблон'!B15 -> 0 | E10: ='1 шаблон'!C15 -> 0 | F10: ='1 шаблон'!D15 -> 0 | G10: =VLOOKUP(E10,'Приложение 15'!$AG$284:$AJ$303,4,0) -> #N/A | H10: 9.4 | I10: =H10 -> 9.4 | J10: =RANDBETWEEN($H10*10,$F10*10)/10 -> #NUM! | K10: =RANDBETWEEN($H10*10,$F10*10)/10 -> #NUM! | L10: =RANDBETWEEN($H10*10,$F10*10)/10 -> #NUM!
C11: ='1 шаблон'!A18 -> 0 | D11: ='1 шаблон'!B17 -> 0 | E11: ='1 шаблон'!C17 -> 0 | F11: ='1 шаблон'!D17 -> 0 | G11: =VLOOKUP(E11,'Приложение 15'!$AG$284:$AJ$303,4,0) -> #N/A | H11: 9.9 | I11: =H11 -> 9.9 | J11: =RANDBETWEEN($H11*10,$F11*10)/10 -> #NUM! | K11: =RANDBETWEEN($H11*10,$F11*10)/10 -> #NUM! | L11: =RANDBETWEEN($H11*10,$F11*10)/10 -> #NUM! | O11: Заполнить | R11: варианты
C12: ='1 шаблон'!A20 -> 0 | D12: ='1 шаблон'!B19 -> 0 | E12: ='1 шаблон'!C19 -> 0 | F12: ='1 шаблон'!D19 -> 0 | G12: =VLOOKUP(E12,'Приложение 15'!$AG$284:$AJ$303,4,0) -> #N/A | H12: 9.9 | I12: =H12 -> 9.9 | J12: =RANDBETWEEN($H12*10,$F12*10)/10 -> #NUM! | K12: =RANDBETWEEN($H12*10,$F12*10)/10 -> #NUM! | L12: =RANDBETWEEN($H12*10,$F12*10)/10 -> #NUM! | O12: Сталь: | P12: Сталь 20 | R12: Сталь 20 | S12: Сталь 10
C13: ='1 шаблон'!A22 -> 0 | D13: ='1 шаблон'!B21 -> 0 | E13: ='1 шаблон'!C21 -> 0 | F13: ='1 шаблон'!D21 -> 0 | G13: =VLOOKUP(E13,'Приложение 15'!$AG$284:$AJ$303,4,0) -> #N/A | H13: 16.9 | I13: =H13 -> 16.9 | J13: =RANDBETWEEN($H13*10,$F13*10)/10 -> #NUM! | K13: =RANDBETWEEN($H13*10,$F13*10)/10 -> #NUM! | L13: =RANDBETWEEN($H13*10,$F13*10)/10 -> #NUM! | O13: Давление | P13: =S13 -> 16 | R13: 4 | S13: 16 | T13: 21 | U13: 0.6
C14: ='1 шаблон'!A24 -> 0 | D14: ='1 шаблон'!B23 -> 0 | E14: ='1 шаблон'!C23 -> 0 | F14: ='1 шаблон'!D23 -> 0 | G14: =VLOOKUP(E14,'Приложение 15'!$AG$284:$AJ$303,4,0) -> #N/A | H14: 15.2 | I14: =H14 -> 15.2 | J14: =RANDBETWEEN($H14*10,$F14*10)/10 -> #NUM! | K14: =RANDBETWEEN($H14*10,$F14*10)/10 -> #NUM! | L14: =RANDBETWEEN($H14*10,$F14*10)/10 -> #NUM! | O14: Среда | P14: НГЖС | R14: НГЖС | S14: вода | U14: газ
C15: ='1 шаблон'!A26 -> 0 | D15: ='1 шаблон'!B25 -> 0 | E15: ='1 шаблон'!C25 -> 0 | F15: ='1 шаблон'!D25 -> 0 | G15: =VLOOKUP(E15,'Приложение 15'!$AG$284:$AJ$303,4,0) -> #N/A | H15: 14.9 | I15: =H15 -> 14.9 | J15: =RANDBETWEEN($H15*10,$F15*10)/10 -> #NUM! | K15: =RANDBETWEEN($H15*10,$F15*10)/10 -> #NUM! | L15: =RANDBETWEEN($H15*10,$F15*10)/10 -> #NUM! | O15: Температура | P15: 10
C16: ='1 шаблон'!A28 -> 0 | D16: ='1 шаблон'!B27 -> 0 | E16: ='1 шаблон'!C27 -> 0 | F16: ='1 шаблон'!D27 -> 0 | G16: =VLOOKUP(E16,'Приложение 15'!$AG$284:$AJ$303,4,0) -> #N/A | H16: 15.4 | I16: =H16 -> 15.4 | J16: =RANDBETWEEN($H16*10,$F16*10)/10 -> #NUM! | K16: =RANDBETWEEN($H16*10,$F16*10)/10 -> #NUM! | L16: =RANDBETWEEN($H16*10,$F16*10)/10 -> #NUM!
C17: ='1 шаблон'!A30 -> 0 | D17: ='1 шаблон'!B29 -> 0 | E17: ='1 шаблон'!C29 -> 0 | F17: ='1 шаблон'!D29 -> 0 | G17: =VLOOKUP(E17,'Приложение 15'!$AG$284:$AJ$303,4,0) -> #N/A | H17: 27.1 | I17: =H17 -> 27.1 | J17: =RANDBETWEEN($H17*10,$F17*10)/10 -> #NUM! | K17: =RANDBETWEEN($H17*10,$F17*10)/10 -> #NUM! | L17: =RANDBETWEEN($H17*10,$F17*10)/10 -> #NUM!
C18: ='1 шаблон'!A32 -> 0 | D18: ='1 шаблон'!B31 -> 0 | E18: ='1 шаблон'!C31 -> 0 | F18: ='1 шаблон'!D31 -> 0 | G18: =VLOOKUP(E18,'Приложение 15'!$AG$284:$AJ$303,4,0) -> #N/A | H18: 28.3 | I18: =H18 -> 28.3 | J18: =RANDBETWEEN($H18*10,$F18*10)/10 -> #NUM! | K18: =RANDBETWEEN($H18*10,$F18*10)/10 -> #NUM! | L18: =RANDBETWEEN($H18*10,$F18*10)/10 -> #NUM!
C19: ='1 шаблон'!A34 -> 0 | D19: ='1 шаблон'!B33 -> 0 | E19: ='1 шаблон'!C33 -> 0 | F19: ='1 шаблон'!D33 -> 0 | G19: =VLOOKUP(E19,'Приложение 15'!$AG$284:$AJ$303,4,0) -> #N/A | H19: 28.2 | I19: =H19 -> 28.2 | J19: =RANDBETWEEN($H19*10,$F19*10)/10 -> #NUM! | K19: =RANDBETWEEN($H19*10,$F19*10)/10 -> #NUM! | L19: =RANDBETWEEN($H19*10,$F19*10)/10 -> #NUM!
C20: ='1 шаблон'!A36 -> 0 | D20: ='1 шаблон'!B35 -> 0 | E20: ='1 шаблон'!C35 -> 0 | F20: ='1 шаблон'!D35 -> 0 | G20: =VLOOKUP(E20,'Приложение 15'!$AG$284:$AJ$303,4,0) -> #N/A | H20: 27.3 | I20: =H20 -> 27.3 | J20: =RANDBETWEEN($H20*10,$F20*10)/10 -> #NUM! | K20: =RANDBETWEEN($H20*10,$F20*10)/10 -> #NUM! | L20: =RANDBETWEEN($H20*10,$F20*10)/10 -> #NUM!
C21: ='1 шаблон'!A38 -> 0 | D21: ='1 шаблон'!B37 -> 0 | E21: ='1 шаблон'!C37 -> 0 | F21: ='1 шаблон'!D37 -> 0 | G21: =VLOOKUP(E21,'Приложение 15'!$AG$284:$AJ$303,4,0) -> #N/A | H21: 27.4 | I21: =H21 -> 27.4 | J21: =RANDBETWEEN($H21*10,$F21*10)/10 -> #NUM! | K21: =RANDBETWEEN($H21*10,$F21*10)/10 -> #NUM! | L21: =RANDBETWEEN($H21*10,$F21*10)/10 -> #NUM!
C22: ='1 шаблон'!A40 -> 0 | D22: ='1 шаблон'!B39 -> 0 | E22: ='1 шаблон'!C39 -> 0 | F22: ='1 шаблон'!D39 -> 0 | G22: =VLOOKUP(E22,'Приложение 15'!$AG$284:$AJ$303,4,0) -> #N/A | H22: 16.8 | I22: =H22 -> 16.8 | J22: =RANDBETWEEN($H22*10,$F22*10)/10 -> #NUM! | K22: =RANDBETWEEN($H22*10,$F22*10)/10 -> #NUM! | L22: =RANDBETWEEN($H22*10,$F22*10)/10 -> #NUM!
C23: ='1 шаблон'!A42 -> 0 | D23: ='1 шаблон'!B41 -> 0 | E23: ='1 шаблон'!C41 -> 0 | F23: ='1 шаблон'!D41 -> 0 | G23: =VLOOKUP(E23,'Приложение 15'!$AG$284:$AJ$303,4,0) -> #N/A | H23: 16.2 | I23: =H23 -> 16.2 | J23: =RANDBETWEEN($H23*10,$F23*10)/10 -> #NUM! | K23: =RANDBETWEEN($H23*10,$F23*10)/10 -> #NUM! | L23: =RANDBETWEEN($H23*10,$F23*10)/10 -> #NUM!
C24: ='1 шаблон'!A44 -> 0 | D24: ='1 шаблон'!B43 -> 0 | E24: ='1 шаблон'!C43 -> 0 | F24: ='1 шаблон'!D43 -> 0 | G24: =VLOOKUP(E24,'Приложение 15'!$AG$284:$AJ$303,4,0) -> #N/A | H24: 16.5 | I24: =H24 -> 16.5 | J24: =RANDBETWEEN($H24*10,$F24*10)/10 -> #NUM! | K24: =RANDBETWEEN($H24*10,$F24*10)/10 -> #NUM! | L24: =RANDBETWEEN($H24*10,$F24*10)/10 -> #NUM!
C25: ='1 шаблон'!A46 -> 0 | D25: ='1 шаблон'!B45 -> 0 | E25: ='1 шаблон'!C45 -> 0 | F25: ='1 шаблон'!D45 -> 0 | G25: =VLOOKUP(E25,'Приложение 15'!$AG$284:$AJ$303,4,0) -> #N/A | H25: 16.5 | I25: =H25 -> 16.5 | J25: =RANDBETWEEN($H25*10,$F25*10)/10 -> #NUM! | K25: =RANDBETWEEN($H25*10,$F25*10)/10 -> #NUM! | L25: =RANDBETWEEN($H25*10,$F25*10)/10 -> #NUM!
H27: Sмин вписывается вручную
B28: Сталь берется из прил 13 | C28: № | D28: Пикет | E28: Диаметр, | F28: Sном, | G28: Sотбр, | H28: Sмин, | I28: Результаты измерений: Нфак., мм
E29: мм | F29: мм | G29: мм | H29: мм | I29: т.1 | J29: т.2 | K29: т.3 | L29: т.4 | M29: т.5 | N29: т.6
A30: 1 | B30: 2 | C30: 1 | D30: 2 | E30: 3 | F30: 4 | G30: 4 | H30: 5 | I30: 6 | J30: 7 | K30: 8 | L30: 9 | M30: 10 | N30: 11 | O30: макс знач
C31: ='1 шаблон'!A53 -> Секция 10 | I31: =RANDBETWEEN($H$32*10,$F$32*10)/10 -> 7.9 | J31: =RANDBETWEEN($H$32*10,$F$32*10)/10 -> 7.9 | K31: =RANDBETWEEN($H$32*10,$F$32*10)/10 -> 8 | L31: =RANDBETWEEN($H$32*10,$F$32*10)/10 -> 8 | M31: =RANDBETWEEN($H$32*10,$F$32*10)/10 -> 7.9 | N31: =RANDBETWEEN($H$32*10,$F$32*10)/10 -> 7.9
A32: =IF(C32="отвод","отвод","труба") -> труба | B32: =VLOOKUP(C31,'2 Приложение 13'!$A$34:$E$245,5,FALSE) -> Сталь 20 | C32: ='1 шаблон'!A54 -> Шурф № 1 | D32: ='1 шаблон'!B53 -> 00+10 | E32: ='1 шаблон'!C53 -> 89 | F32: ='1 шаблон'!D53 -> 8 | G32: =SUMPRODUCT((A32='Приложение 15'!$AE$3:$AE$282)*('3 Прил 12 (толщинометрия)'!E32='Приложение 15'!$AG$3:$AG$282)*('3 Прил 12 (толщинометрия)'!B32='Приложение 15'!$AH$3:$AH$282)*('3 Прил 12 (толщинометрия)'!$P$13='Приложение 15'!$AF$3:$AF$282)*('3 Прил 12 (толщинометрия)'!$P$14='Приложение 15'!$AI$3:$AI$282)*'Приложение 15'!$AJ$3:$AJ$282) -> 0 | H32: 7.8 | I32: =H32 -> 7.8 | J32: =RANDBETWEEN($H$32*10,$F$32*10)/10 -> 7.9 | K32: =RANDBETWEEN($H$32*10,$F$32*10)/10 -> 8 | L32: =RANDBETWEEN($H$32*10,$F$32*10)/10 -> 7.8 | M32: =RANDBETWEEN($H$32*10,$F$32*10)/10 -> 7.8 | N32: =RANDBETWEEN($H$32*10,$F$32*10)/10 -> 7.9 | O32: =MAX(I31:N33) -> 8 | Q32: шурф | R32: труба | S32: отвод | T32: переход | U32: тройник | V32: заглушка
I33: =RANDBETWEEN($H$32*10,$F$32*10)/10 -> 7.8 | J33: =RANDBETWEEN($H$32*10,$F$32*10)/10 -> 7.8 | K33: =RANDBETWEEN($H$32*10,$F$32*10)/10 -> 7.9 | L33: =RANDBETWEEN($H$32*10,$F$32*10)/10 -> 8 | M33: =RANDBETWEEN($H$32*10,$F$32*10)/10 -> 7.8 | N33: =RANDBETWEEN($H$32*10,$F$32*10)/10 -> 7.8
C34: ='1 шаблон'!A56 -> Секция 20 | I34: =RANDBETWEEN($H$35*10,$F$35*10)/10 -> 8 | J34: =RANDBETWEEN($H$35*10,$F$35*10)/10 -> 7.9 | K34: =RANDBETWEEN($H$35*10,$F$35*10)/10 -> 8 | L34: =RANDBETWEEN($H$35*10,$F$35*10)/10 -> 7.8 | M34: =RANDBETWEEN($H$35*10,$F$35*10)/10 -> 7.8 | N34: =RANDBETWEEN($H$35*10,$F$35*10)/10 -> 8
A35: =IF(C35="отвод","отвод","труба") -> труба | B35: =VLOOKUP(C34,'2 Приложение 13'!$A$34:$E$245,5,FALSE) -> Сталь 20 | C35: ='1 шаблон'!A57 -> труба | D35: ='1 шаблон'!B56 -> 00+20 | E35: ='1 шаблон'!C56 -> 89 | F35: ='1 шаблон'!D56 -> 8 | G35: =SUMPRODUCT((A35='Приложение 15'!$AE$3:$AE$282)*('3 Прил 12 (толщинометрия)'!E35='Приложение 15'!$AG$3:$AG$282)*('3 Прил 12 (толщинометрия)'!B35='Приложение 15'!$AH$3:$AH$282)*('3 Прил 12 (толщинометрия)'!$P$13='Приложение 15'!$AF$3:$AF$282)*('3 Прил 12 (толщинометрия)'!$P$14='Приложение 15'!$AI$3:$AI$282)*'Приложение 15'!$AJ$3:$AJ$282) -> 0 | H35: 7.8 | I35: =H35 -> 7.8 | J35: =RANDBETWEEN($H$35*10,$F$35*10)/10 -> 8 | K35: =RANDBETWEEN($H$35*10,$F$35*10)/10 -> 8 | L35: =RANDBETWEEN($H$35*10,$F$35*10)/10 -> 8 | M35: =RANDBETWEEN($H$35*10,$F$35*10)/10 -> 8 | N35: =RANDBETWEEN($H$35*10,$F$35*10)/10 -> 7.8 | O35: =MAX(I34:N36) -> 8
I36: =RANDBETWEEN($H$35*10,$F$35*10)/10 -> 7.8 | J36: =RANDBETWEEN($H$35*10,$F$35*10)/10 -> 7.9 | K36: =RANDBETWEEN($H$35*10,$F$35*10)/10 -> 7.8 | L36: =RANDBETWEEN($H$35*10,$F$35*10)/10 -> 7.9 | M36: =RANDBETWEEN($H$35*10,$F$35*10)/10 -> 8 | N36: =RANDBETWEEN($H$35*10,$F$35*10)/10 -> 8
C37: ='1 шаблон'!A59 -> 0 | I37: =RANDBETWEEN($H$38*10,$F$38*10)/10 -> #NUM! | J37: =RANDBETWEEN($H$38*10,$F$38*10)/10 -> #NUM! | K37: =RANDBETWEEN($H$38*10,$F$38*10)/10 -> #NUM! | L37: =RANDBETWEEN($H$38*10,$F$38*10)/10 -> #NUM! | M37: =RANDBETWEEN($H$38*10,$F$38*10)/10 -> #NUM! | N37: =RANDBETWEEN($H$38*10,$F$38*10)/10 -> #NUM!
A38: =IF(C38="отвод","отвод","труба") -> труба | B38: =VLOOKUP(C37,'2 Приложение 13'!$A$34:$E$245,5,FALSE) -> Сталь 20 | C38: ='1 шаблон'!A60 -> 0 | D38: ='1 шаблон'!B59 -> 0 | E38: ='1 шаблон'!C59 -> 0 | F38: ='1 шаблон'!D59 -> 0 | G38: =SUMPRODUCT((A38='Приложение 15'!$AE$3:$AE$282)*('3 Прил 12 (толщинометрия)'!E38='Приложение 15'!$AG$3:$AG$282)*('3 Прил 12 (толщинометрия)'!B38='Приложение 15'!$AH$3:$AH$282)*('3 Прил 12 (толщинометрия)'!$P$13='Приложение 15'!$AF$3:$AF$282)*('3 Прил 12 (толщинометрия)'!$P$14='Приложение 15'!$AI$3:$AI$282)*'Приложение 15'!$AJ$3:$AJ$282) -> 0 | H38: 7.4 | I38: =H38 -> 7.4 | J38: =RANDBETWEEN($H$38*10,$F$38*10)/10 -> #NUM! | K38: =RANDBETWEEN($H$38*10,$F$38*10)/10 -> #NUM! | L38: =RANDBETWEEN($H$38*10,$F$38*10)/10 -> #NUM! | M38: =RANDBETWEEN($H$38*10,$F$38*10)/10 -> #NUM! | N38: =RANDBETWEEN($H$38*10,$F$38*10)/10 -> #NUM! | O38: =MAX(I37:N39) -> #NUM!
I39: =RANDBETWEEN($H$38*10,$F$38*10)/10 -> #NUM! | J39: =RANDBETWEEN($H$38*10,$F$38*10)/10 -> #NUM! | K39: =RANDBETWEEN($H$38*10,$F$38*10)/10 -> #NUM! | L39: =RANDBETWEEN($H$38*10,$F$38*10)/10 -> #NUM! | M39: =RANDBETWEEN($H$38*10,$F$38*10)/10 -> #NUM! | N39: =RANDBETWEEN($H$38*10,$F$38*10)/10 -> #NUM!
C40: ='1 шаблон'!A62 -> 0 | I40: =RANDBETWEEN($H$41*10,$F$41*10)/10 -> #NUM! | J40: =RANDBETWEEN($H$41*10,$F$41*10)/10 -> #NUM! | K40: =RANDBETWEEN($H$41*10,$F$41*10)/10 -> #NUM! | L40: =RANDBETWEEN($H$41*10,$F$41*10)/10 -> #NUM! | M40: =RANDBETWEEN($H$41*10,$F$41*10)/10 -> #NUM! | N40: =RANDBETWEEN($H$41*10,$F$41*10)/10 -> #NUM!
A41: =IF(C41="отвод","отвод","труба") -> труба | B41: =VLOOKUP(C40,'2 Приложение 13'!$A$34:$E$245,5,FALSE) -> Сталь 20 | C41: ='1 шаблон'!A63 -> 0 | D41: ='1 шаблон'!B62 -> 0 | E41: ='1 шаблон'!C62 -> 0 | F41: ='1 шаблон'!D62 -> 0 | G41: =SUMPRODUCT((A41='Приложение 15'!$AE$3:$AE$282)*('3 Прил 12 (толщинометрия)'!E41='Приложение 15'!$AG$3:$AG$282)*('3 Прил 12 (толщинометрия)'!B41='Приложение 15'!$AH$3:$AH$282)*('3 Прил 12 (толщинометрия)'!$P$13='Приложение 15'!$AF$3:$AF$282)*('3 Прил 12 (толщинометрия)'!$P$14='Приложение 15'!$AI$3:$AI$282)*'Приложение 15'!$AJ$3:$AJ$282) -> 0 | H41: 7.9 | I41: =H41 -> 7.9 | J41: =RANDBETWEEN($H$41*10,$F$41*10)/10 -> #NUM! | K41: =RANDBETWEEN($H$41*10,$F$41*10)/10 -> #NUM! | L41: =RANDBETWEEN($H$41*10,$F$41*10)/10 -> #NUM! | M41: =RANDBETWEEN($H$41*10,$F$41*10)/10 -> #NUM! | N41: =RANDBETWEEN($H$41*10,$F$41*10)/10 -> #NUM! | O41: =MAX(I40:N42) -> #NUM!
...

Sheet 3 Прил 12 (Чистовик+вывод)
B1: Обозачения по цветам: | D1: ЗКЛ | E1: ОК | F1: ЗДШ | M1: при помощи фильтров (по цвету и обычные) выбираем нужный нам элемент поочередно отфильтровывая название эл-та (по цвету), диаметр и номинальную толщину
M3: для каждого индивидуально элемента нужно делать вывод отдельно
C5: =CONCATENATE("Остаточная толщина стенок ",D1,": Ø",SUBTOTAL(1,C15:C35),"х",FIXED(SUBTOTAL(1,D15:D35),"1")," мм составляет ",FIXED(SUBTOTAL(5,F15:I35),"1"),"÷",FIXED(SUBTOTAL(4,F15:I35),"1")," мм.") -> Остаточная толщина стенок ЗКЛ: Ø5,41666666666667х1,3 мм составляет 15,9÷16,0 мм. | M5: копируем готовый вывод
C7: =CONCATENATE("Остаточная толщина стенок ",E1,": Ø",SUBTOTAL(1,C15:C35),"х",FIXED(SUBTOTAL(1,D15:D35),"1")," мм составляет ",FIXED(SUBTOTAL(5,F15:I35),"1"),"÷",FIXED(SUBTOTAL(4,F15:I35),"1")," мм.") -> Остаточная толщина стенок ОК: Ø5,41666666666667х1,3 мм составляет 15,9÷16,0 мм. | M7: отбраковочная рассчитывается автоматически
C9: =CONCATENATE("Остаточная толщина стенок ",F1,": Ø",SUBTOTAL(1,C15:C35),"х",FIXED(SUBTOTAL(1,D15:D35),"1")," мм составляет ",FIXED(SUBTOTAL(5,F15:I35),"1"),"÷",FIXED(SUBTOTAL(4,F15:I35),"1")," мм.") -> Остаточная толщина стенок ЗДШ: Ø5,41666666666667х1,3 мм составляет 15,9÷16,0 мм.
A11: Таблица для ОК, ЗКЛ, ЗДШ
A12: № | B12: Пикет | C12: Ду, мм | D12: Sном, | E12: ='3 Прил 12 (толщинометрия)'!G2 -> Sотбр, | F12: Результаты измерений: Нфак., мм | J12: Sмин, | K12: Sмах,
D13: мм | E13: ='3 Прил 12 (толщинометрия)'!G3 -> мм | F13: т.1 | G13: т.2 | H13: т.3 | I13: т.4 | J13: мм | K13: мм
A14: 1 | B14: 2 | C14: 3 | D14: 4 | E14: 5 | F14: 6 | G14: 7 | H14: 8 | I14: 9 | J14: 10 | K14: 11
A15: ='3 Прил 12 (толщинометрия)'!C5 -> ЗМС | B15: ='3 Прил 12 (толщинометрия)'!D5 -> 00+20 | C15: ='3 Прил 12 (толщинометрия)'!E5 -> 65 | D15: ='3 Прил 12 (толщинометрия)'!F5 -> 16 | E15: ='3 Прил 12 (толщинометрия)'!G5 -> #N/A | F15: 15.9 | G15: 16 | H15: 16 | I15: 16 | J15: =MIN(F15:I15) -> 15.9 | K15: =MAX(F15:I15) -> 16
A16: ='3 Прил 12 (толщинометрия)'!C6 -> 0 | B16: ='3 Прил 12 (толщинометрия)'!D6 -> 0 | C16: ='3 Прил 12 (толщинометрия)'!E6 -> 0 | D16: ='3 Прил 12 (толщинометрия)'!F6 -> 0 | E16: ='3 Прил 12 (толщинометрия)'!G6 -> #N/A | J16: =MIN(F16:I16) -> 0 | K16: =MAX(F16:I16) -> 0
A17: ='3 Прил 12 (толщинометрия)'!C7 -> 0 | B17: ='3 Прил 12 (толщинометрия)'!D7 -> 0 | C17: ='3 Прил 12 (толщинометрия)'!E7 -> 0 | D17: ='3 Прил 12 (толщинометрия)'!F7 -> 0 | E17: ='3 Прил 12 (толщинометрия)'!G7 -> #N/A | J17: =MIN(F17:I17) -> 0 | K17: =MAX(F17:I17) -> 0
A18: ='3 Прил 12 (толщинометрия)'!C8 -> 0 | B18: ='3 Прил 12 (толщинометрия)'!D8 -> 0 | C18: ='3 Прил 12 (толщинометрия)'!E8 -> 0 | D18: ='3 Прил 12 (толщинометрия)'!F8 -> 0 | E18: ='3 Прил 12 (толщинометрия)'!G8 -> #N/A | J18: =MIN(F18:I18) -> 0 | K18: =MAX(F18:I18) -> 0
A19: ='3 Прил 12 (толщинометрия)'!C9 -> 0 | B19: ='3 Прил 12 (толщинометрия)'!D9 -> 0 | C19: ='3 Прил 12 (толщинометрия)'!E9 -> 0 | D19: ='3 Прил 12 (толщинометрия)'!F9 -> 0 | E19: ='3 Прил 12 (толщинометрия)'!G9 -> #N/A | J19: =MIN(F19:I19) -> 0 | K19: =MAX(F19:I19) -> 0
A20: ='3 Прил 12 (толщинометрия)'!C10 -> 0 | B20: ='3 Прил 12 (толщинометрия)'!D10 -> 0 | C20: ='3 Прил 12 (толщинометрия)'!E10 -> 0 | D20: ='3 Прил 12 (толщинометрия)'!F10 -> 0 | E20: ='3 Прил 12 (толщинометрия)'!G10 -> #N/A | J20: =MIN(F20:I20) -> 0 | K20: =MAX(F20:I20) -> 0
A21: ='3 Прил 12 (толщинометрия)'!C11 -> 0 | B21: ='3 Прил 12 (толщинометрия)'!D11 -> 0 | C21: ='3 Прил 12 (толщинометрия)'!E11 -> 0 | D21: ='3 Прил 12 (толщинометрия)'!F11 -> 0 | E21: ='3 Прил 12 (толщинометрия)'!G11 -> #N/A | J21: =MIN(F21:I21) -> 0 | K21: =MAX(F21:I21) -> 0
A22: ='3 Прил 12 (толщинометрия)'!C12 -> 0 | B22: ='3 Прил 12 (толщинометрия)'!D12 -> 0 | C22: ='3 Прил 12 (толщинометрия)'!E12 -> 0 | D22: ='3 Прил 12 (толщинометрия)'!F12 -> 0 | E22: ='3 Прил 12 (толщинометрия)'!G12 -> #N/A | J22: =MIN(F22:I22) -> 0 | K22: =MAX(F22:I22) -> 0
A23: ='3 Прил 12 (толщинометрия)'!C13 -> 0 | B23: ='3 Прил 12 (толщинометрия)'!D13 -> 0 | C23: ='3 Прил 12 (толщинометрия)'!E13 -> 0 | D23: ='3 Прил 12 (толщинометрия)'!F13 -> 0 | E23: ='3 Прил 12 (толщинометрия)'!G13 -> #N/A | J23: =MIN(F23:I23) -> 0 | K23: =MAX(F23:I23) -> 0
A24: ='3 Прил 12 (толщинометрия)'!C14 -> 0 | B24: ='3 Прил 12 (толщинометрия)'!D14 -> 0 | C24: ='3 Прил 12 (толщинометрия)'!E14 -> 0 | D24: ='3 Прил 12 (толщинометрия)'!F14 -> 0 | E24: ='3 Прил 12 (толщинометрия)'!G14 -> #N/A | J24: =MIN(F24:I24) -> 0 | K24: =MAX(F24:I24) -> 0
A25: ='3 Прил 12 (толщинометрия)'!C15 -> 0 | B25: ='3 Прил 12 (толщинометрия)'!D15 -> 0 | C25: ='3 Прил 12 (толщинометрия)'!E15 -> 0 | D25: ='3 Прил 12 (толщинометрия)'!F15 -> 0 | E25: ='3 Прил 12 (толщинометрия)'!G15 -> #N/A | J25: =MIN(F25:I25) -> 0 | K25: =MAX(F25:I25) -> 0
A26: ='3 Прил 12 (толщинометрия)'!C16 -> 0 | B26: ='3 Прил 12 (толщинометрия)'!D16 -> 0 | C26: ='3 Прил 12 (толщинометрия)'!E16 -> 0 | D26: ='3 Прил 12 (толщинометрия)'!F16 -> 0 | E26: ='3 Прил 12 (толщинометрия)'!G16 -> #N/A | J26: =MIN(F26:I26) -> 0 | K26: =MAX(F26:I26) -> 0
E37: шурф
E38: труба | F38: отвод | G38: переход | H38: тройник | I38: заглушка
C39: Обозачения по цветам: | E39: трубопровода | F39: отвода | G39: перехода | H39: тройника | I39: заглушки
D44: =CONCATENATE("Остаточная толщина стенок ",E39,": Ø",SUBTOTAL(1,$C$57:$C$6596),"х",FIXED(SUBTOTAL(1,$D$57:$D$6596),"1")," мм составляет ",FIXED(SUBTOTAL(5,$M$57:$M$6596),"1"),"÷",FIXED(SUBTOTAL(4,$L$57:$L$659),"1")," мм.") -> Остаточная толщина стенок трубопровода: Ø0,709163346613546х0,1 мм составляет 5,3÷8,0 мм.
D46: =CONCATENATE("Остаточная толщина стенок ",F39,": Ø",SUBTOTAL(1,$C$57:$C$6593),"х",FIXED(SUBTOTAL(1,$D$57:$D$6596),"1")," мм составляет ",FIXED(SUBTOTAL(5,$M$57:$M$6592),"1"),"÷",FIXED(SUBTOTAL(4,$L$57:$L$659),"1")," мм.") -> Остаточная толщина стенок отвода: Ø0,709163346613546х0,1 мм составляет 5,3÷8,0 мм.
D48: =CONCATENATE("Остаточная толщина стенок ",G39,": Ø",SUBTOTAL(1,$C$57:$C$6593),"х",FIXED(SUBTOTAL(1,$D$57:$D$6593),"1")," мм составляет ",FIXED(SUBTOTAL(5,$M$57:$M$6593),"1"),"÷",FIXED(SUBTOTAL(4,$L$57:$L$659),"1")," мм.") -> Остаточная толщина стенок перехода: Ø0,709163346613546х0,1 мм составляет 5,3÷8,0 мм.
D50: =CONCATENATE("Остаточная толщина стенок ",H39,": Ø",SUBTOTAL(1,$C$57:$C$6596),"х",FIXED(SUBTOTAL(1,$D$57:$D$6596),"1")," мм составляет ",FIXED(SUBTOTAL(5,$M$57:$M$6596),"1"),"÷",FIXED(SUBTOTAL(4,$L$57:$L$659),"1")," мм.") -> Остаточная толщина стенок тройника: Ø0,709163346613546х0,1 мм составляет 5,3÷8,0 мм.
D52: =CONCATENATE("Остаточная толщина стенок ",I39,": Ø",SUBTOTAL(1,$C$57:$C$6596),"х",FIXED(SUBTOTAL(1,$D$57:$D$6596),"1")," мм составляет ",FIXED(SUBTOTAL(5,$M$57:$M$659),"1"),"÷",FIXED(SUBTOTAL(4,$L$57:$L$659),"1")," мм.") -> Остаточная толщина стенок заглушки: Ø0,709163346613546х0,1 мм составляет 5,3÷8,0 мм.
A54: № | B54: Пикет | C54: Диаметр, | D54: Sном, | E54: ='3 Прил 12 (толщинометрия)'!G28 -> Sотбр, | F54: Результаты измерений: Нфак., мм | L54: Sмах, | M54: Sмин,
C55: мм | D55: мм | E55: мм | F55: т.1 | G55: т.2 | H55: т.3 | I55: т.4 | J55: т.5 | K55: т.6 | L55: мм | M55: мм
A56: 1 | B56: 2 | C56: 3 | D56: 4 | E56: 5 | F56: 6 | G56: 7 | H56: 8 | I56: 9 | J56: 10 | K56: 11 | L56: 12 | M56: 13
A57: ='3 Прил 12 (толщинометрия)'!C31 -> Секция 10 | F57: 8 | G57: 7.9 | H57: 7.8 | I57: 7.8 | J57: 7.9 | K57: 8
A58: ='3 Прил 12 (толщинометрия)'!C32 -> Шурф № 1 | B58: ='3 Прил 12 (толщинометрия)'!D32 -> 00+10 | C58: ='3 Прил 12 (толщинометрия)'!E32 -> 89 | D58: ='3 Прил 12 (толщинометрия)'!F32 -> 8 | E58: ='3 Прил 12 (толщинометрия)'!G32 -> 0 | F58: 7.8 | G58: 7.9 | H58: 8 | I58: 8 | J58: 8 | K58: 7.8 | L58: =MAX(F57:K59) -> 8 | M58: ='3 Прил 12 (толщинометрия)'!H32 -> 7.8
F59: 8 | G59: 8 | H59: 8 | I59: 7.9 | J59: 7.8 | K59: 7.8
A60: ='3 Прил 12 (толщинометрия)'!C34 -> Секция 20 | F60: 7.8 | G60: 7.8 | H60: 7.9 | I60: 7.8 | J60: 7.8 | K60: 8
A61: ='3 Прил 12 (толщинометрия)'!C35 -> труба | B61: ='3 Прил 12 (толщинометрия)'!D35 -> 00+20 | C61: ='3 Прил 12 (толщинометрия)'!E35 -> 89 | D61: ='3 Прил 12 (толщинометрия)'!F35 -> 8 | E61: ='3 Прил 12 (толщинометрия)'!G35 -> 0 | F61: 7.8 | G61: 7.9 | H61: 8 | I61: 7.8 | J61: 7.9 | K61: 7.8 | L61: =MAX(F60:K62) -> 8 | M61: ='3 Прил 12 (толщинометрия)'!H35 -> 7.8
F62: 7.9 | G62: 8 | H62: 7.9 | I62: 8 | J62: 7.9 | K62: 7.9
A63: ='3 Прил 12 (толщинометрия)'!C37 -> 0
A64: ='3 Прил 12 (толщинометрия)'!C38 -> 0 | B64: ='3 Прил 12 (толщинометрия)'!D38 -> 0 | C64: ='3 Прил 12 (толщинометрия)'!E38 -> 0 | D64: ='3 Прил 12 (толщинометрия)'!F38 -> 0 | E64: ='3 Прил 12 (толщинометрия)'!G38 -> 0 | L64: =MAX(F63:K65) -> 0 | M64: ='3 Прил 12 (толщинометрия)'!H38 -> 7.4
...

Sheet для прил4
G2: Значения берутся автоматически из Прил 12 (чистовик) и Прил 13 (чистовик)
A3: № | B3: Наим | C3: Пикет | D3: Толщина | E3: Твердость
